Workbook

Sheet RETIRADOS
A1: Angela Hurtado | E1: Baleria Orias
A2: 1113630071 | E2: 1006287986
A6: Aura Adelfa Alvarez Vinasco | E6: Catalina Palacio Perez
A7: 31469693 | E7: 43978294
A11: Angie Paola Serrano Franco | E11: Camilo Andres Lopez Bolaños
A12: 1043985561 | E12: 1061694194
A17: Angela Maria Ramirez | E17: Claudia Patricia Ortega Vidal
A18: 1118302471 | E18: 29115270
A23: Anderson Dayan Iter Enriquez | E23: Darly Julieth Alvarez
A24: 1113067116 | E24: 1118284277
A29: Eduard Steven Martinez Muñoz | E29: Francisco Javier Lopez Correa
A30: 1109187236 | E30: 18590428
A35: Fernando Cordoba | E35: Heber Cardenas
A36: 16464886 | E36: 1006536580
A41: Isabella Bermudez Lopez | E41: Isabella Gomez Ramirez
A42: 1107642330 | E42: 1116374501
A47: Johana Garzon | E47: Arcila Gil Juan Alquiber
A48: 31485571 | E48: 94253614
A53: Johan Esteban Cabrera | E53: Jenny Andrea Osorio
A54: 1109184541 | E54: 40627634
A59: Jose Reinaldo Hernandez | E59: Jenifer Tatiana Caicedo Albaran
A60: 6550612 | E60: 1113680163
A65: Jhonier Arguello | E65: Otero Jesus
A66: 1118307511 | E66: 16448182
A71: Johan Ochoa | E71: Julio Cesar Buitrago
A72: 1118309510 | E72: 1130638035
A76: Jose Javier Tangarife Giraldo | E76: Jose Ignacio Giraldo Hoyos
A77: 16369039 | E77: 6549736
A82: Janovis Karelia Hernandez | E82: Jhon Paladines
A83: 6347470 | E83: 1116373358
A88: Jorge Ivan Gonzales | E88: Jose Rebeiro Lame Pino
A89: 6531539 | E89: 1126451838
A93: Jhon Jairo Mora Guzman | E93: Julian David Arboleda Saavedra
A94: 7728555 | E94: 110989512
A99: Jose Davinson Riascos | E99: Jerson Ipus Agudelo
A100: 1111775892 | E100: 1006436196
A104: Karen Tatiana Bravo | E104: Kensy Yulieth Franco
A105: 1063722921 | E105: 1052730520
A110: Karen Marcela Perez Nieva | E110: Luis Carlos Suarez
A111: 1236438574 | E111: 16454804
...

Sheet A
A1: Yumbo, 30 Noviembre 2025 | E1: Cuenta de Cobro | G1: 23-949
A3: Yo
A4: Con C.C
A5: Manifiesto que: FUNDACION UNA MANO AMIGA A TIEMPO NIT: 901.369.891-9
A9: ME DEBE LA SUMA DE: | C9: 645000
A10: VALOR EN PESOS: | C10: =ARRAY_CONSTRAIN(ARRAYFORMULA(UPPER([1]!NumLetra(C9,,"PESOS"))), 1, 1) -> #ERROR!
A11: POR CONCEPTO DE: | C11: PRESTACION DE SERVICIOS
A13: Declaro voluntariamente y bajo la gravedad de juramento, que no soy responsable del impuesto del IVA. Declaro que mis ingresos mensuales provienen de la compensación por servicios personales y que para obtenerlos no he contratado ni vinculado dos (2) o más trabajadores asociados a la actividad. Lo anterior con el propósito de ser beneficiario en el cálculo de la retención en la fuente por concepto de honorarios, según lo dispuesto en el art 383 del estatuto tributario.
A21: FIRMA
A25: =A1 -> Yumbo, 30 Noviembre 2025 | E25: Cuenta de Cobro | G25: 23-951
A27: Yo | B27: Angie Melissa Arredondo Garzon
A28: Con C.C | B28: 100779358
A29: Manifiesto que: FUNDACION UNA MANO AMIGA A TIEMPO NIT: 901.369.891-9
A33: ME DEBE LA SUMA DE: | C33: 600000
A34: VALOR EN PESOS: | C34: =ARRAY_CONSTRAIN(ARRAYFORMULA(UPPER([1]!NumLetra(C33,,"PESOS"))), 1, 1) -> #ERROR!
A35: POR CONCEPTO DE: | C35: PRESTACION DE SERVICIOS
A37: Declaro voluntariamente y bajo la gravedad de juramento, que no soy responsable del impuesto del IVA. Declaro que mis ingresos mensuales provienen de la compensación por servicios personales y que para obtenerlos no he contratado ni vinculado dos (2) o más trabajadores asociados a la actividad. Lo anterior con el propósito de ser beneficiario en el cálculo de la retención en la fuente por concepto de honorarios, según lo dispuesto en el art 383 del estatuto tributario.
A45: FIRMA
A49: =A25 -> Yumbo, 30 Noviembre 2025 | E49: Cuenta de Cobro | G49: 23-951
A51: Yo | B51: Alejandro Rubianes Realpe
A52: Con C.C | B52: 1105366389
A53: Manifiesto que: FUNDACION UNA MANO AMIGA A TIEMPO NIT: 901.369.891-9
A57: ME DEBE LA SUMA DE: | C57: 240000
A58: VALOR EN PESOS: | C58: =ARRAY_CONSTRAIN(ARRAYFORMULA(UPPER([1]!NumLetra(C57,,"PESOS"))), 1, 1) -> #ERROR!
A59: POR CONCEPTO DE: | C59: PRESTACION DE SERVICIOS
A61: Declaro voluntariamente y bajo la gravedad de juramento, que no soy responsable del impuesto del IVA. Declaro que mis ingresos mensuales provienen de la compensación por servicios personales y que para obtenerlos no he contratado ni vinculado dos (2) o más trabajadores asociados a la actividad. Lo anterior con el propósito de ser beneficiario en el cálculo de la retención en la fuente por concepto de honorarios, según lo dispuesto en el art 383 del estatuto tributario.
A69: FIRMA
A76: 46146 | E76: Cuenta de Cobro
A78: Yo | B78: Ana Isabella Gil
A79: Con C.C | B79: 38557504
A80: Manifiesto que: FUNDACION UNA MANO AMIGA A TIEMPO NIT: 901.369.891-9
A84: ME DEBE LA SUMA DE: | C84: 68000
A85: VALOR EN PESOS: | C85: Sesenta y ocho mil pesos.
A86: POR CONCEPTO DE: | C86: PRESTACION DE SERVICIOS
A88: Declaro voluntariamente y bajo la gravedad de juramento, que no soy responsable del impuesto del IVA. Declaro que mis ingresos mensuales provienen de la compensación por servicios personales y que para obtenerlos no he contratado ni vinculado dos (2) o más trabajadores asociados a la actividad. Lo anterior con el propósito de ser beneficiario en el cálculo de la retención en la fuente por concepto de honorarios, según lo dispuesto en el art 383 del estatuto tributario.
A96: FIRMA

Sheet B
A1: =A!A25 -> Yumbo, 30 Noviembre 2025 | E1: Cuenta de Cobro | G1: 23-986
A3: Yo | B3: Bertha Yulieth Cerón Perlaza
A4: Con C.C | B4: 1118302461
A5: Manifiesto que: FUNDACION UNA MANO AMIGA A TIEMPO NIT: 901.369.891-9
A9: ME DEBE LA SUMA DE: | C9: 255000
A10: VALOR EN PESOS: | C10: =ARRAY_CONSTRAIN(ARRAYFORMULA(UPPER([1]!NumLetra(C33,,"PESOS"))), 1, 1) -> #ERROR!
A11: POR CONCEPTO DE: | C11: PRESTACION DE SERVICIOS
A13: Declaro voluntariamente y bajo la gravedad de juramento, que no soy responsable del impuesto del IVA. Declaro que mis ingresos mensuales provienen de la compensación por servicios personales y que para obtenerlos no he contratado ni vinculado dos (2) o más trabajadores asociados a la actividad. Lo anterior con el propósito de ser beneficiario en el cálculo de la retención en la fuente por concepto de honorarios, según lo dispuesto en el art 383 del estatuto tributario.
A21: FIRMA

Sheet C
A1: =D!A1 -> Yumbo, 30 Noviembre 2025 | E1: Cuenta de Cobro | G1: 23-974
A3: Yo | B3: Galarza Carlos Andres
A4: Con C.C | B4: 16461107
A5: Manifiesto que: FUNDACION UNA MANO AMIGA A TIEMPO NIT: 901.369.891-9
A9: ME DEBE LA SUMA DE: | C9: 255000
A10: VALOR EN PESOS: | C10: =ARRAY_CONSTRAIN(ARRAYFORMULA(UPPER([1]!NumLetra(C9,,"PESOS"))), 1, 1) -> #ERROR!
A11: POR CONCEPTO DE: | C11: PRESTACION DE SERVICIOS
A13: Declaro voluntariamente y bajo la gravedad de juramento, que no soy responsable del impuesto del IVA. Declaro que mis ingresos mensuales provienen de la compensación por servicios personales y que para obtenerlos no he contratado ni vinculado dos (2) o más trabajadores asociados a la actividad. Lo anterior con el propósito de ser beneficiario en el cálculo de la retención en la fuente por concepto de honorarios, según lo dispuesto en el art 383 del estatuto tributario.
A21: FIRMA
A25: =#REF! -> #REF! | E25: Cuenta de Cobro | G25: 23-995
A27: Yo | B27: Claudia Alvarez Gonzales
A28: Con C.C | B28: 1093214577
A29: Manifiesto que: FUNDACION UNA MANO AMIGA A TIEMPO NIT: 901.369.891-9
A33: ME DEBE LA SUMA DE: | C33: 255000
A34: VALOR EN PESOS: | C34: =ARRAY_CONSTRAIN(ARRAYFORMULA(UPPER([1]!NumLetra(C177,,"PESOS"))), 1, 1) -> #ERROR!
A35: POR CONCEPTO DE: | C35: PRESTACION SERVICIOS
A37: Declaro voluntariamente y bajo la gravedad de juramento, que no soy responsable del impuesto del IVA. Declaro que mis ingresos mensuales provienen de la compensación por servicios personales y que para obtenerlos no he contratado ni vinculado dos (2) o más trabajadores asociados a la actividad. Lo anterior con el propósito de ser beneficiario en el cálculo de la retención en la fuente por concepto de honorarios, según lo dispuesto en el art 383 del estatuto tributario.
A45: FIRMA

Sheet D
A1: =A!A1 -> Yumbo, 30 Noviembre 2025 | E1: Cuenta de Cobro
A3: Yo | B3: Diana Carolina Arias Vasquez
A4: Con C.C | B4: 1007779173
A5: Manifiesto que: FUNDACION UNA MANO AMIGA A TIEMPO NIT: 901.369.891-9
A9: ME DEBE LA SUMA DE: | C9: 255000
A10: VALOR EN PESOS: | C10: =ARRAY_CONSTRAIN(ARRAYFORMULA(UPPER([1]!NumLetra(C9,,"PESOS"))), 1, 1) -> #ERROR!
A11: POR CONCEPTO DE: | C11: SERVICIOS PRESTADOS
A13: Declaro voluntariamente y bajo la gravedad de juramento, que no soy responsable del impuesto del IVA. Declaro que mis ingresos mensuales provienen de la compensación por servicios personales y que para obtenerlos no he contratado ni vinculado dos (2) o más trabajadores asociados a la actividad. Lo anterior con el propósito de ser beneficiario en el cálculo de la retención en la fuente por concepto de honorarios, según lo dispuesto en el art 383 del estatuto tributario.
A21: FIRMA
A25: =A1 -> Yumbo, 30 Noviembre 2025 | E25: Cuenta de Cobro | G25: 23-973
A27: Yo | B27: Diana Lorena Riacos Mejia
A28: Con C.C | B28: 1118290778
A29: Manifiesto que: FUNDACION UNA MANO AMIGA A TIEMPO NIT: 901.369.891-9
A33: ME DEBE LA SUMA DE: | C33: 345000
A34: VALOR EN PESOS: | C34: =ARRAY_CONSTRAIN(ARRAYFORMULA(UPPER([1]!NumLetra(C33,,"PESOS"))), 1, 1) -> #ERROR!
A35: POR CONCEPTO DE: | C35: PRESTACION DE SERVICIOS
A37: Declaro voluntariamente y bajo la gravedad de juramento, que no soy responsable del impuesto del IVA. Declaro que mis ingresos mensuales provienen de la compensación por servicios personales y que para obtenerlos no he contratado ni vinculado dos (2) o más trabajadores asociados a la actividad. Lo anterior con el propósito de ser beneficiario en el cálculo de la retención en la fuente por concepto de honorarios, según lo dispuesto en el art 383 del estatuto tributario.
A45: FIRMA
A49: =#REF! -> #REF! | E49: Cuenta de Cobro | G49: 23-982
A51: Yo | B51: Donella Garzon Salazar
A52: Con C.C | B52: 29939491
A53: Manifiesto que: FUNDACION UNA MANO AMIGA A TIEMPO NIT: 901.369.891-9
A57: ME DEBE LA SUMA DE: | C57: 350250
A58: VALOR EN PESOS: | C58: =ARRAY_CONSTRAIN(ARRAYFORMULA(UPPER([1]!NumLetra(C81,,"PESOS"))), 1, 1) -> #ERROR!
A59: POR CONCEPTO DE: | C59: PRESTACION DE SERVICIOS
A61: Declaro voluntariamente y bajo la gravedad de juramento, que no soy responsable del impuesto del IVA. Declaro que mis ingresos mensuales provienen de la compensación por servicios personales y que para obtenerlos no he contratado ni vinculado dos (2) o más trabajadores asociados a la actividad. Lo anterior con el propósito de ser beneficiario en el cálculo de la retención en la fuente por concepto de honorarios, según lo dispuesto en el art 383 del estatuto tributario.
A69: FIRMA

Sheet E
A1: =A!A25 -> Yumbo, 30 Noviembre 2025 | E1: Cuenta de Cobro | G1: 23-949
A3: Yo | B3: Garzon Eloisa
A4: Con C.C | B4: 31483643
A5: Manifiesto que: FUNDACION UNA MANO AMIGA A TIEMPO NIT: 901.369.891-9
A9: ME DEBE LA SUMA DE: | C9: 645000
A10: VALOR EN PESOS: | C10: =ARRAY_CONSTRAIN(ARRAYFORMULA(UPPER([1]!NumLetra(C9,,"PESOS"))), 1, 1) -> #ERROR!
A11: POR CONCEPTO DE: | C11: PRESTACION DE SERVICIOS
A13: Declaro voluntariamente y bajo la gravedad de juramento, que no soy responsable del impuesto del IVA. Declaro que mis ingresos mensuales provienen de la compensación por servicios personales y que para obtenerlos no he contratado ni vinculado dos (2) o más trabajadores asociados a la actividad. Lo anterior con el propósito de ser beneficiario en el cálculo de la retención en la fuente por concepto de honorarios, según lo dispuesto en el art 383 del estatuto tributario.
A21: FIRMA
A25: =E!A1 -> Yumbo, 30 Noviembre 2025 | E25: Cuenta de Cobro | G25: 23-962
A27: Yo | B27: Eider Pabon Montenegro
A28: Con C.C | B28: 16453190
A29: Manifiesto que: FUNDACION UNA MANO AMIGA A TIEMPO NIT: 901.369.891-9
A33: ME DEBE LA SUMA DE: | C33: 255000
A34: VALOR EN PESOS: | C34: =ARRAY_CONSTRAIN(ARRAYFORMULA(UPPER([1]!NumLetra(C33,,"PESOS"))), 1, 1) -> #ERROR!
A35: POR CONCEPTO DE: | C35: PRESTACION DE SERVICIOS
A37: Declaro voluntariamente y bajo la gravedad de juramento, que no soy responsable del impuesto del IVA. Declaro que mis ingresos mensuales provienen de la compensación por servicios personales y que para obtenerlos no he contratado ni vinculado dos (2) o más trabajadores asociados a la actividad. Lo anterior con el propósito de ser beneficiario en el cálculo de la retención en la fuente por concepto de honorarios, según lo dispuesto en el art 383 del estatuto tributario.
A45: FIRMA
A49: =A73 -> #REF! | E49: Cuenta de Cobro | G49: 23-959
A51: Yo | B51: Esteban Alejandro Arias Vaquez
A52: Con C.C | B52: 1006072723
A53: Manifiesto que: FUNDACION UNA MANO AMIGA A TIEMPO NIT: 901.369.891-9
A57: ME DEBE LA SUMA DE: | C57: 255000
A58: VALOR EN PESOS: | C58: =ARRAY_CONSTRAIN(ARRAYFORMULA(UPPER([1]!NumLetra(C57,,"PESOS"))), 1, 1) -> #ERROR!
A59: POR CONCEPTO DE: | C59: PRESTACION DE SERVICIOS
A61: Declaro voluntariamente y bajo la gravedad de juramento, que no soy responsable del impuesto del IVA. Declaro que mis ingresos mensuales provienen de la compensación por servicios personales y que para obtenerlos no he contratado ni vinculado dos (2) o más trabajadores asociados a la actividad. Lo anterior con el propósito de ser beneficiario en el cálculo de la retención en la fuente por concepto de honorarios, según lo dispuesto en el art 383 del estatuto tributario.
A69: FIRMA
A73: =#REF! -> #REF! | E73: Cuenta de Cobro | G73: 23-993
A75: Yo | B75: Emilce Mayorga Rivera
A76: Con C.C | B76: 1114727110
A77: Manifiesto que: FUNDACION UNA MANO AMIGA A TIEMPO NIT: 901.369.891-9
A81: ME DEBE LA SUMA DE: | C81: 255000
A82: VALOR EN PESOS: | C82: =ARRAY_CONSTRAIN(ARRAYFORMULA(UPPER([1]!NumLetra(C81,,"PESOS"))), 1, 1) -> #ERROR!
A83: POR CONCEPTO DE: | C83: PRESTACION DE SERVICIOS
A85: Declaro voluntariamente y bajo la gravedad de juramento, que no soy responsable del impuesto del IVA. Declaro que mis ingresos mensuales provienen de la compensación por servicios personales y que para obtenerlos no he contratado ni vinculado dos (2) o más trabajadores asociados a la actividad. Lo anterior con el propósito de ser beneficiario en el cálculo de la retención en la fuente por concepto de honorarios, según lo dispuesto en el art 383 del estatuto tributario.
A93: FIRMA
A97: =A!$A$25 -> Yumbo, 30 Noviembre 2025 | E97: Cuenta de Cobro | G97: 23-949
A99: Yo | B99: Erika Iter
A100: Con C.C | B100: 1113067117
A101: Manifiesto que: FUNDACION UNA MANO AMIGA A TIEMPO NIT: 901.369.891-9
...

Sheet G
A1: =A!A1 -> Yumbo, 30 Noviembre 2025 | E1: Cuenta de Cobro | G1: 23-963
A3: Yo | B3: Guillermo Dominguez
A4: Con C.C | B4: 16461820
A5: Manifiesto que: FUNDACION UNA MANO AMIGA A TIEMPO NIT: 901.369.891-9
A9: ME DEBE LA SUMA DE: | C9: 55000
A10: VALOR EN PESOS: | C10: =ARRAY_CONSTRAIN(ARRAYFORMULA(UPPER([1]!NumLetra(C9,,"PESOS"))), 1, 1) -> #ERROR!
A11: POR CONCEPTO DE: | C11: PRESTACION DE SERVICIOS
A13: Declaro voluntariamente y bajo la gravedad de juramento, que no soy responsable del impuesto del IVA. Declaro que mis ingresos mensuales provienen de la compensación por servicios personales y que para obtenerlos no he contratado ni vinculado dos (2) o más trabajadores asociados a la actividad. Lo anterior con el propósito de ser beneficiario en el cálculo de la retención en la fuente por concepto de honorarios, según lo dispuesto en el art 383 del estatuto tributario.
A21: FIRMA
A25: =A1 -> Yumbo, 30 Noviembre 2025 | E25: Cuenta de Cobro | G25: 23-975
A27: Yo | B27: Gildardo Emilio Moscoso Soto
A28: Con C.C | B28: 7510791
A29: Manifiesto que: FUNDACION UNA MANO AMIGA A TIEMPO NIT: 901.369.891-9
A33: ME DEBE LA SUMA DE: | C33: 345000
A34: VALOR EN PESOS: | C34: =ARRAY_CONSTRAIN(ARRAYFORMULA(UPPER([1]!NumLetra(C33,,"PESOS"))), 1, 1) -> #ERROR!
A35: POR CONCEPTO DE: | C35: PRESTACION DE SERVICIOS
A37: Declaro voluntariamente y bajo la gravedad de juramento, que no soy responsable del impuesto del IVA. Declaro que mis ingresos mensuales provienen de la compensación por servicios personales y que para obtenerlos no he contratado ni vinculado dos (2) o más trabajadores asociados a la actividad. Lo anterior con el propósito de ser beneficiario en el cálculo de la retención en la fuente por concepto de honorarios, según lo dispuesto en el art 383 del estatuto tributario.
A45: FIRMA
A49: =#REF! -> #REF! | E49: Cuenta de Cobro | G49: 23-979
A51: Yo | B51: =[3]Hoja1!B47 -> #ERROR!
A52: Con C.C | B52: =[3]Hoja1!A47 -> #ERROR!
A53: Manifiesto que: FUNDACION UNA MANO AMIGA A TIEMPO NIT: 901.369.891-9
A57: ME DEBE LA SUMA DE: | C57: 272000
A58: VALOR EN PESOS: | C58: =ARRAY_CONSTRAIN(ARRAYFORMULA(UPPER([1]!NumLetra(C57,,"PESOS"))), 1, 1) -> #ERROR!
A59: POR CONCEPTO DE: | C59: PRESTACION DE SERVICIOS
A61: Declaro voluntariamente y bajo la gravedad de juramento, que no soy responsable del impuesto del IVA. Declaro que mis ingresos mensuales provienen de la compensación por servicios personales y que para obtenerlos no he contratado ni vinculado dos (2) o más trabajadores asociados a la actividad. Lo anterior con el propósito de ser beneficiario en el cálculo de la retención en la fuente por concepto de honorarios, según lo dispuesto en el art 383 del estatuto tributario.
A69: FIRMA
A73: =#REF! -> #REF! | E73: Cuenta de Cobro | G73: 23-979
A75: Yo | B75: Gabriel Elias Guerrrero
A76: Con C.C | B76: 1109920831
A77: Manifiesto que: FUNDACION UNA MANO AMIGA A TIEMPO NIT: 901.369.891-9
A81: ME DEBE LA SUMA DE: | C81: 126300
A82: VALOR EN PESOS: | C82: =ARRAY_CONSTRAIN(ARRAYFORMULA(UPPER([1]!NumLetra(C81,,"PESOS"))), 1, 1) -> #ERROR!
A83: POR CONCEPTO DE: | C83: PRESTACION DE SERVICIOS
A85: Declaro voluntariamente y bajo la gravedad de juramento, que no soy responsable del impuesto del IVA. Declaro que mis ingresos mensuales provienen de la compensación por servicios personales y que para obtenerlos no he contratado ni vinculado dos (2) o más trabajadores asociados a la actividad. Lo anterior con el propósito de ser beneficiario en el cálculo de la retención en la fuente por concepto de honorarios, según lo dispuesto en el art 383 del estatuto tributario.
A93: FIRMA

Sheet F
A1: =E!A1 -> Yumbo, 30 Noviembre 2025 | E1: Cuenta de Cobro | G1: 23-994
A3: Yo | B3: Fredy Antonio Ospina Gomez
A4: Con C.C | B4: 94404511
A5: Manifiesto que: FUNDACION UNA MANO AMIGA A TIEMPO NIT: 901.369.891-9
A9: ME DEBE LA SUMA DE: | C9: 255000
A10: VALOR EN PESOS: | C10: =ARRAY_CONSTRAIN(ARRAYFORMULA(UPPER([1]!NumLetra(C9,,"PESOS"))), 1, 1) -> #ERROR!
A11: POR CONCEPTO DE: | C11: PRESTACION DE SERVICIOS
A13: Declaro voluntariamente y bajo la gravedad de juramento, que no soy responsable del impuesto del IVA. Declaro que mis ingresos mensuales provienen de la compensación por servicios personales y que para obtenerlos no he contratado ni vinculado dos (2) o más trabajadores asociados a la actividad. Lo anterior con el propósito de ser beneficiario en el cálculo de la retención en la fuente por concepto de honorarios, según lo dispuesto en el art 383 del estatuto tributario.
A22: FIRMA

Sheet H
A1: =A!A1 -> Yumbo, 30 Noviembre 2025 | E1: Cuenta de Cobro | G1: 23-949
A3: Yo | B3: Herney Andres Zuñiga Gamboa
A4: Con C.C | B4: 1116373114
A5: Manifiesto que: FUNDACION UNA MANO AMIGA A TIEMPO NIT: 901.369.891-9
A9: ME DEBE LA SUMA DE: | C9: 84200
A10: VALOR EN PESOS: | C10: =ARRAY_CONSTRAIN(ARRAYFORMULA(UPPER([1]!NumLetra(C9,,"PESOS"))), 1, 1) -> #ERROR!
A11: POR CONCEPTO DE: | C11: PRESTACION DE SERVICIOS
A13: Declaro voluntariamente y bajo la gravedad de juramento, que no soy responsable del impuesto del IVA. Declaro que mis ingresos mensuales provienen de la compensación por servicios personales y que para obtenerlos no he contratado ni vinculado dos (2) o más trabajadores asociados a la actividad. Lo anterior con el propósito de ser beneficiario en el cálculo de la retención en la fuente por concepto de honorarios, según lo dispuesto en el art 383 del estatuto tributario.
A21: FIRMA
A25: =#REF! -> #REF! | E25: Cuenta de Cobro | G25: 23-949
A27: Yo | B27: Hiroshi Takata Garcia
A28: Con C.C | B28: 94379974
A29: Manifiesto que: FUNDACION UNA MANO AMIGA A TIEMPO NIT: 901.369.891-9
A33: ME DEBE LA SUMA DE: | C33: 18600
A34: VALOR EN PESOS: | C34: =ARRAY_CONSTRAIN(ARRAYFORMULA(UPPER([1]!NumLetra(C57,,"PESOS"))), 1, 1) -> #ERROR!
A35: POR CONCEPTO DE: | C35: PRESTACION DE SERVICIOS
A37: Declaro voluntariamente y bajo la gravedad de juramento, que no soy responsable del impuesto del IVA. Declaro que mis ingresos mensuales provienen de la compensación por servicios personales y que para obtenerlos no he contratado ni vinculado dos (2) o más trabajadores asociados a la actividad. Lo anterior con el propósito de ser beneficiario en el cálculo de la retención en la fuente por concepto de honorarios, según lo dispuesto en el art 383 del estatuto tributario.
A45: FIRMA

Sheet I

Sheet J
A1: =A!A1 -> Yumbo, 30 Noviembre 2025 | E1: Cuenta de Cobro | G1: 23-958
A3: Yo | B3: Granada Jhoan Sebastian
A4: Con C.C | B4: 118306042
A5: Manifiesto que: FUNDACION UNA MANO AMIGA A TIEMPO NIT: 901.369.891-9
A9: ME DEBE LA SUMA DE: | C9: 238000
A10: VALOR EN PESOS: | C10: =ARRAY_CONSTRAIN(ARRAYFORMULA(UPPER([1]!NumLetra(C57,,"PESOS"))), 1, 1) -> #ERROR!
A11: POR CONCEPTO DE: | C11: PRESTACION DE SERVICIOS
A13: Declaro voluntariamente y bajo la gravedad de juramento, que no soy responsable del impuesto del IVA. Declaro que mis ingresos mensuales provienen de la compensación por servicios personales y que para obtenerlos no he contratado ni vinculado dos (2) o más trabajadores asociados a la actividad. Lo anterior con el propósito de ser beneficiario en el cálculo de la retención en la fuente por concepto de honorarios, según lo dispuesto en el art 383 del estatuto tributario.
A21: FIRMA
A25: =E!A1 -> Yumbo, 30 Noviembre 2025 | E25: Cuenta de Cobro | G25: 23-980
A27: Yo | B27: Jolman Agusto Tamayo Ipus
A28: Con C.C | B28: 83250261
A29: Manifiesto que: FUNDACION UNA MANO AMIGA A TIEMPO NIT: 901.369.891-9
A33: ME DEBE LA SUMA DE: | C33: 432500
A34: VALOR EN PESOS: | C34: =ARRAY_CONSTRAIN(ARRAYFORMULA(UPPER([1]!NumLetra(C177,,"PESOS"))), 1, 1) -> #ERROR!
A35: POR CONCEPTO DE: | C35: PRESTACION DE SERVICIOS
A37: Declaro voluntariamente y bajo la gravedad de juramento, que no soy responsable del impuesto del IVA. Declaro que mis ingresos mensuales provienen de la compensación por servicios personales y que para obtenerlos no he contratado ni vinculado dos (2) o más trabajadores asociados a la actividad. Lo anterior con el propósito de ser beneficiario en el cálculo de la retención en la fuente por concepto de honorarios, según lo dispuesto en el art 383 del estatuto tributario.
A45: FIRMA
A49: =E!A1 -> Yumbo, 30 Noviembre 2025 | E49: Cuenta de Cobro | G49: 23-971
A51: Yo | B51: John Jairo Castañeda Pascua
A52: Con C.C | B52: 10127217
A53: Manifiesto que: FUNDACION UNA MANO AMIGA A TIEMPO NIT: 901.369.891-9
A57: ME DEBE LA SUMA DE: | C57: 368000
A58: VALOR EN PESOS: | C58: =ARRAY_CONSTRAIN(ARRAYFORMULA(UPPER([1]!NumLetra(C249,,"PESOS"))), 1, 1) -> #ERROR!
A59: POR CONCEPTO DE: | C59: PRESTACION DE SERVICIOS
A61: Declaro voluntariamente y bajo la gravedad de juramento, que no soy responsable del impuesto del IVA. Declaro que mis ingresos mensuales provienen de la compensación por servicios personales y que para obtenerlos no he contratado ni vinculado dos (2) o más trabajadores asociados a la actividad. Lo anterior con el propósito de ser beneficiario en el cálculo de la retención en la fuente por concepto de honorarios, según lo dispuesto en el art 383 del estatuto tributario.
A69: FIRMA
A73: =E!A1 -> Yumbo, 30 Noviembre 2025 | E73: Cuenta de Cobro | G73: 23-960
A75: Yo | B75: Jose Leonel Ospina
A76: Con C.C | B76: ='[7]PLANILLA MATRIX'!$A$30 -> #REF!
A77: Manifiesto que: FUNDACION UNA MANO AMIGA A TIEMPO NIT: 901.369.891-9
A81: ME DEBE LA SUMA DE: | C81: 261375
A82: VALOR EN PESOS: | C82: =ARRAY_CONSTRAIN(ARRAYFORMULA(UPPER([1]!NumLetra(C273,,"PESOS"))), 1, 1) -> #ERROR!
A83: POR CONCEPTO DE: | C83: PRESTACION DE SERVICIOS
A85: Declaro voluntariamente y bajo la gravedad de juramento, que no soy responsable del impuesto del IVA. Declaro que mis ingresos mensuales provienen de la compensación por servicios personales y que para obtenerlos no he contratado ni vinculado dos (2) o más trabajadores asociados a la actividad. Lo anterior con el propósito de ser beneficiario en el cálculo de la retención en la fuente por concepto de honorarios, según lo dispuesto en el art 383 del estatuto tributario.
A93: FIRMA
A97: =#REF! -> #REF! | E97: Cuenta de Cobro | G97: 23-997
A99: Yo | B99: Juan Esteban Hurtado
A100: Con C.C | B100: 1014194949
A101: Manifiesto que: FUNDACION UNA MANO AMIGA A TIEMPO NIT: 901.369.891-9
...

Sheet K
A1: =#REF! -> #REF! | E1: Cuenta de Cobro | G1: 23-997
A3: Yo | B3: Katherine Velez Cabrera
A4: Con C.C | B4: 1118293542
A5: Manifiesto que: FUNDACION UNA MANO AMIGA A TIEMPO NIT: 901.369.891-9
A9: ME DEBE LA SUMA DE: | C9: 300000
A10: VALOR EN PESOS: | C10: =ARRAY_CONSTRAIN(ARRAYFORMULA(UPPER([1]!NumLetra(C57,,"PESOS"))), 1, 1) -> #ERROR!
A11: POR CONCEPTO DE: | C11: PRESTACIÓN DE SERVICIOS
A13: Declaro voluntariamente y bajo la gravedad de juramento, que no soy responsable del impuesto del IVA. Declaro que mis ingresos mensuales provienen de la compensación por servicios personales y que para obtenerlos no he contratado ni vinculado dos (2) o más trabajadores asociados a la actividad. Lo anterior con el propósito de ser beneficiario en el cálculo de la retención en la fuente por concepto de honorarios, según lo dispuesto en el art 383 del estatuto tributario.
A21: FIRMA
A25: =#REF! -> #REF! | E25: Cuenta de Cobro | G25: 23-997
A27: Yo | B27: Karen Lorena Galvis
A28: Con C.C | B28: 1116306268
A29: Manifiesto que: FUNDACION UNA MANO AMIGA A TIEMPO NIT: 901.369.891-9
A33: ME DEBE LA SUMA DE: | C33: 80000
A34: VALOR EN PESOS: | C34: =ARRAY_CONSTRAIN(ARRAYFORMULA(UPPER([1]!NumLetra(C81,,"PESOS"))), 1, 1) -> #ERROR!
A35: POR CONCEPTO DE: | C35: TURNOS PENDIENTES DE LA 1RA QUINCENA DE ENERO
A37: Declaro voluntariamente y bajo la gravedad de juramento, que no soy responsable del impuesto del IVA. Declaro que mis ingresos mensuales provienen de la compensación por servicios personales y que para obtenerlos no he contratado ni vinculado dos (2) o más trabajadores asociados a la actividad. Lo anterior con el propósito de ser beneficiario en el cálculo de la retención en la fuente por concepto de honorarios, según lo dispuesto en el art 383 del estatuto tributario.
A45: FIRMA
A49: =A1 -> #REF! | E49: Cuenta de Cobro | G49: 23-997
A51: Yo | B51: Kevin Galvis Sanabria
A52: Con C.C | B52: 1118301640
A53: Manifiesto que: FUNDACION UNA MANO AMIGA A TIEMPO NIT: 901.369.891-9
A57: ME DEBE LA SUMA DE: | C57: 84200
A58: VALOR EN PESOS: | C58: =ARRAY_CONSTRAIN(ARRAYFORMULA(UPPER([1]!NumLetra(C129,,"PESOS"))), 1, 1) -> #ERROR!
A59: POR CONCEPTO DE: | C59: PRESTACION DE SERVICIOS
A61: Declaro voluntariamente y bajo la gravedad de juramento, que no soy responsable del impuesto del IVA. Declaro que mis ingresos mensuales provienen de la compensación por servicios personales y que para obtenerlos no he contratado ni vinculado dos (2) o más trabajadores asociados a la actividad. Lo anterior con el propósito de ser beneficiario en el cálculo de la retención en la fuente por concepto de honorarios, según lo dispuesto en el art 383 del estatuto tributario.
A69: FIRMA

Sheet L
A1: =#REF! -> #REF! | E1: Cuenta de Cobro | G1: 23-995
A3: Yo | B3: Luis Alberto Morales Calvo
A4: Con C.C | B4: 16448514
A5: Manifiesto que: FUNDACION UNA MANO AMIGA A TIEMPO NIT: 901.369.891-9
A9: ME DEBE LA SUMA DE: | C9: 255000
A10: VALOR EN PESOS: | C10: =ARRAY_CONSTRAIN(ARRAYFORMULA(UPPER([1]!NumLetra(C105,,"PESOS"))), 1, 1) -> #ERROR!
A11: POR CONCEPTO DE: | C11: PRESTACION SERVICIOS
A13: Declaro voluntariamente y bajo la gravedad de juramento, que no soy responsable del impuesto del IVA. Declaro que mis ingresos mensuales provienen de la compensación por servicios personales y que para obtenerlos no he contratado ni vinculado dos (2) o más trabajadores asociados a la actividad. Lo anterior con el propósito de ser beneficiario en el cálculo de la retención en la fuente por concepto de honorarios, según lo dispuesto en el art 383 del estatuto tributario.
A21: FIRMA
A25: =#REF! -> #REF! | E25: Cuenta de Cobro | G25: 23-995
A27: Yo | B27: Lilian Maria Salasar
A28: Con C.C | B28: 66858781
A29: Manifiesto que: FUNDACION UNA MANO AMIGA A TIEMPO NIT: 901.369.891-9
A33: ME DEBE LA SUMA DE: | C33: 144000
A34: VALOR EN PESOS: | C34: =ARRAY_CONSTRAIN(ARRAYFORMULA(UPPER([1]!NumLetra(C153,,"PESOS"))), 1, 1) -> #ERROR!
A35: POR CONCEPTO DE: | C35: PRESTACION SERVICIOS
A37: Declaro voluntariamente y bajo la gravedad de juramento, que no soy responsable del impuesto del IVA. Declaro que mis ingresos mensuales provienen de la compensación por servicios personales y que para obtenerlos no he contratado ni vinculado dos (2) o más trabajadores asociados a la actividad. Lo anterior con el propósito de ser beneficiario en el cálculo de la retención en la fuente por concepto de honorarios, según lo dispuesto en el art 383 del estatuto tributario.
A45: FIRMA
A50: =#REF! -> #REF! | E50: Cuenta de Cobro | G50: 23-995
A52: Yo | B52: Laura Ordoñez
A53: Con C.C | B53: 1090274163
A54: Manifiesto que: FUNDACION UNA MANO AMIGA A TIEMPO NIT: 901.369.891-9
A58: ME DEBE LA SUMA DE: | C58: 126300
A59: VALOR EN PESOS: | C59: =ARRAY_CONSTRAIN(ARRAYFORMULA(UPPER([1]!NumLetra(C225,,"PESOS"))), 1, 1) -> #ERROR!
A60: POR CONCEPTO DE: | C60: PRESTACION SERVICIOS
A62: Declaro voluntariamente y bajo la gravedad de juramento, que no soy responsable del impuesto del IVA. Declaro que mis ingresos mensuales provienen de la compensación por servicios personales y que para obtenerlos no he contratado ni vinculado dos (2) o más trabajadores asociados a la actividad. Lo anterior con el propósito de ser beneficiario en el cálculo de la retención en la fuente por concepto de honorarios, según lo dispuesto en el art 383 del estatuto tributario.
A70: FIRMA

Sheet M
A1: =#REF! -> #REF! | E1: Cuenta de Cobro | G1: 23-950
A3: Yo | B3: Mildred Alexandra Llanten Fernandez
A4: Con C.C | B4: 1118295832
A5: Manifiesto que: FUNDACION UNA MANO AMIGA A TIEMPO NIT: 901.369.891-9
A9: ME DEBE LA SUMA DE: | C9: 255000
A10: VALOR EN PESOS: | C10: =ARRAY_CONSTRAIN(ARRAYFORMULA(UPPER([1]!NumLetra(C9,,"PESOS"))), 1, 1) -> #ERROR!
A11: POR CONCEPTO DE: | C11: PRESTACION DE SERVICIOS
A13: Declaro voluntariamente y bajo la gravedad de juramento, que no soy responsable del impuesto del IVA. Declaro que mis ingresos mensuales provienen de la compensación por servicios personales y que para obtenerlos no he contratado ni vinculado dos (2) o más trabajadores asociados a la actividad. Lo anterior con el propósito de ser beneficiario en el cálculo de la retención en la fuente por concepto de honorarios, según lo dispuesto en el art 383 del estatuto tributario.
A21: FIRMA
A25: =#REF! -> #REF! | E25: Cuenta de Cobro | G25: 23-977
A27: Yo | B27: Marcos Alvarez
A28: Con C.C | B28: 16446859
A29: Manifiesto que: FUNDACION UNA MANO AMIGA A TIEMPO NIT: 901.369.891-9
A33: ME DEBE LA SUMA DE: | C33: 278375
A34: VALOR EN PESOS: | C34: =ARRAY_CONSTRAIN(ARRAYFORMULA(UPPER([1]!NumLetra(C201,,"PESOS"))), 1, 1) -> #ERROR!
A35: POR CONCEPTO DE: | C35: PRESTACION DE SERVICIOS
A37: Declaro voluntariamente y bajo la gravedad de juramento, que no soy responsable del impuesto del IVA. Declaro que mis ingresos mensuales provienen de la compensación por servicios personales y que para obtenerlos no he contratado ni vinculado dos (2) o más trabajadores asociados a la actividad. Lo anterior con el propósito de ser beneficiario en el cálculo de la retención en la fuente por concepto de honorarios, según lo dispuesto en el art 383 del estatuto tributario.
A45: FIRMA
A49: =$A$1 -> #REF! | E49: Cuenta de Cobro | G49: 23-977
A51: Yo | B51: Monica Vernaza Loango
A52: Con C.C | B52: 1113671746
A53: Manifiesto que: FUNDACION UNA MANO AMIGA A TIEMPO NIT: 901.369.891-9
A57: ME DEBE LA SUMA DE: | C57: 352500
A58: VALOR EN PESOS: | C58: =ARRAY_CONSTRAIN(ARRAYFORMULA(UPPER([1]!NumLetra(C249,,"PESOS"))), 1, 1) -> #ERROR!
A59: POR CONCEPTO DE: | C59: PRESTACION DE SERVICIOS
A61: Declaro voluntariamente y bajo la gravedad de juramento, que no soy responsable del impuesto del IVA. Declaro que mis ingresos mensuales provienen de la compensación por servicios personales y que para obtenerlos no he contratado ni vinculado dos (2) o más trabajadores asociados a la actividad. Lo anterior con el propósito de ser beneficiario en el cálculo de la retención en la fuente por concepto de honorarios, según lo dispuesto en el art 383 del estatuto tributario.
A69: FIRMA
A73: =$A$1 -> #REF! | E73: Cuenta de Cobro | G73: 23-977
A75: Yo | B75: Mariland Agudelo
A76: Con C.C | B76: 66932221
A77: Manifiesto que: FUNDACION UNA MANO AMIGA A TIEMPO NIT: 901.369.891-9
A81: ME DEBE LA SUMA DE: | C81: 255000
A82: VALOR EN PESOS: | C82: =ARRAY_CONSTRAIN(ARRAYFORMULA(UPPER([1]!NumLetra(C273,,"PESOS"))), 1, 1) -> #ERROR!
A83: POR CONCEPTO DE: | C83: PRESTACION DE SERVICIOS
A85: Declaro voluntariamente y bajo la gravedad de juramento, que no soy responsable del impuesto del IVA. Declaro que mis ingresos mensuales provienen de la compensación por servicios personales y que para obtenerlos no he contratado ni vinculado dos (2) o más trabajadores asociados a la actividad. Lo anterior con el propósito de ser beneficiario en el cálculo de la retención en la fuente por concepto de honorarios, según lo dispuesto en el art 383 del estatuto tributario.
A93: FIRMA
A97: =$A$1 -> #REF! | E97: Cuenta de Cobro | G97: 23-977
A99: Yo | B99: Maria Yesenia Loango Velasco
A100: Con C.C | B100: 66932221
A101: Manifiesto que: FUNDACION UNA MANO AMIGA A TIEMPO NIT: 901.369.891-9
...

Sheet N
A1: =#REF! -> #REF! | E1: Cuenta de Cobro | G1: 23-961
A3: Yo | B3: Noe Contreras
A4: Con C.C | B4: 1118291407
A5: Manifiesto que: FUNDACION UNA MANO AMIGA A TIEMPO NIT: 901.369.891-9
A9: ME DEBE LA SUMA DE: | C9: 600000
A10: VALOR EN PESOS: | C10: =ARRAY_CONSTRAIN(ARRAYFORMULA(UPPER([1]!NumLetra(C9,,"PESOS"))), 1, 1) -> #ERROR!
A11: POR CONCEPTO DE: | C11: PRESTACION DE SERVICIOS
A13: Declaro voluntariamente y bajo la gravedad de juramento, que no soy responsable del impuesto del IVA. Declaro que mis ingresos mensuales provienen de la compensación por servicios personales y que para obtenerlos no he contratado ni vinculado dos (2) o más trabajadores asociados a la actividad. Lo anterior con el propósito de ser beneficiario en el cálculo de la retención en la fuente por concepto de honorarios, según lo dispuesto en el art 383 del estatuto tributario.
A21: FIRMA

Sheet O
A1: =M!$A$25 -> #REF! | E1: Cuenta de Cobro | G1: 23-984
A3: Yo | B3: Onney Cuartas
A4: Con C.C | B4: 16269074
A5: Manifiesto que: FUNDACION UNA MANO AMIGA A TIEMPO NIT: 901.369.891-9
A9: ME DEBE LA SUMA DE: | C9: 352500
A10: VALOR EN PESOS: | C10: =ARRAY_CONSTRAIN(ARRAYFORMULA(UPPER([1]!NumLetra(C9,,"PESOS"))), 1, 1) -> #ERROR!
A11: POR CONCEPTO DE: | C11: PRESTACION DE SERVICIOS
A13: Declaro voluntariamente y bajo la gravedad de juramento, que no soy responsable del impuesto del IVA. Declaro que mis ingresos mensuales provienen de la compensación por servicios personales y que para obtenerlos no he contratado ni vinculado dos (2) o más trabajadores asociados a la actividad. Lo anterior con el propósito de ser beneficiario en el cálculo de la retención en la fuente por concepto de honorarios, según lo dispuesto en el art 383 del estatuto tributario.
A21: FIRMA
A25: =M!$A$25 -> #REF! | E25: Cuenta de Cobro | G25: 23-984
A27: Yo | B27: Omaira Alejandra Chacon
A28: Con C.C | B28: 1114542641
A29: Manifiesto que: FUNDACION UNA MANO AMIGA A TIEMPO NIT: 901.369.891-9
A33: ME DEBE LA SUMA DE: | C33: 204000
A34: VALOR EN PESOS: | C34: =ARRAY_CONSTRAIN(ARRAYFORMULA(UPPER([1]!NumLetra(C33,,"PESOS"))), 1, 1) -> #ERROR!
A35: POR CONCEPTO DE: | C35: PRESTACION DE SERVICIOS
A37: Declaro voluntariamente y bajo la gravedad de juramento, que no soy responsable del impuesto del IVA. Declaro que mis ingresos mensuales provienen de la compensación por servicios personales y que para obtenerlos no he contratado ni vinculado dos (2) o más trabajadores asociados a la actividad. Lo anterior con el propósito de ser beneficiario en el cálculo de la retención en la fuente por concepto de honorarios, según lo dispuesto en el art 383 del estatuto tributario.
A45: FIRMA

Sheet P
A1: =M!A25 -> #REF! | E1: Cuenta de Cobro | G1: 23-977
A3: Yo | B3: Parmenides Noreña
A4: Con C.C | B4: 16590651
A5: Manifiesto que: FUNDACION UNA MANO AMIGA A TIEMPO NIT: 901.369.891-9
A9: ME DEBE LA SUMA DE: | C9: 266000
A10: VALOR EN PESOS: | C10: =ARRAY_CONSTRAIN(ARRAYFORMULA(UPPER([1]!NumLetra(C9,,"PESOS"))), 1, 1) -> #ERROR!
A11: POR CONCEPTO DE: | C11: PRESTACION DE SERVICIOS
A13: Declaro voluntariamente y bajo la gravedad de juramento, que no soy responsable del impuesto del IVA. Declaro que mis ingresos mensuales provienen de la compensación por servicios personales y que para obtenerlos no he contratado ni vinculado dos (2) o más trabajadores asociados a la actividad. Lo anterior con el propósito de ser beneficiario en el cálculo de la retención en la fuente por concepto de honorarios, según lo dispuesto en el art 383 del estatuto tributario.
A21: FIRMA

Sheet Q

Sheet R

Sheet S

Sheet T

Sheet U

Sheet V

Sheet W
A1: =#REF! -> #REF! | E1: Cuenta de Cobro | G1: 23-949
A3: Yo | B3: Wilson Añasco
A4: Con C.C | B4: 16455352
A5: Manifiesto que: FUNDACION UNA MANO AMIGA A TIEMPO NIT: 901.369.891-9
A9: ME DEBE LA SUMA DE: | C9: 62000
A10: VALOR EN PESOS: | C10: =ARRAY_CONSTRAIN(ARRAYFORMULA(UPPER([1]!NumLetra(C33,,"PESOS"))), 1, 1) -> #ERROR!
A11: POR CONCEPTO DE: | C11: PRESTACION DE SERVICIOS
A13: Declaro voluntariamente y bajo la gravedad de juramento, que no soy responsable del impuesto del IVA. Declaro que mis ingresos mensuales provienen de la compensación por servicios personales y que para obtenerlos no he contratado ni vinculado dos (2) o más trabajadores asociados a la actividad. Lo anterior con el propósito de ser beneficiario en el cálculo de la retención en la fuente por concepto de honorarios, según lo dispuesto en el art 383 del estatuto tributario.
A21: FIRMA

Sheet X

Sheet Y
A1: =#REF! -> #REF! | E1: Cuenta de Cobro | G1: 23-995
A3: Yo | B3: Yamileth Miranda
A4: Con C.C | B4: 314888255
A5: Manifiesto que: FUNDACION UNA MANO AMIGA A TIEMPO NIT: 901.369.891-9
A9: ME DEBE LA SUMA DE: | C9: 204000
A10: VALOR EN PESOS: | C10: =ARRAY_CONSTRAIN(ARRAYFORMULA(UPPER([1]!NumLetra(C81,,"PESOS"))), 1, 1) -> #ERROR!
A11: POR CONCEPTO DE: | C11: PRESTACION SERVICIOS
A13: Declaro voluntariamente y bajo la gravedad de juramento, que no soy responsable del impuesto del IVA. Declaro que mis ingresos mensuales provienen de la compensación por servicios personales y que para obtenerlos no he contratado ni vinculado dos (2) o más trabajadores asociados a la actividad. Lo anterior con el propósito de ser beneficiario en el cálculo de la retención en la fuente por concepto de honorarios, según lo dispuesto en el art 383 del estatuto tributario.
A21: FIRMA

Sheet Z
A1: =A!A1 -> Yumbo, 30 Noviembre 2025 | E1: Cuenta de Cobro | G1: 23-986
A3: Yo | B3: Zharich Nikol Polanco Garzón
A4: Con C.C | B4: 1193412592
A5: Manifiesto que: FUNDACION UNA MANO AMIGA A TIEMPO NIT: 901.369.891-9
A9: ME DEBE LA SUMA DE: | C9: 100000
A10: VALOR EN PESOS: | C10: =ARRAY_CONSTRAIN(ARRAYFORMULA(UPPER([1]!NumLetra(C9,,"PESOS"))), 1, 1) -> #ERROR!
A11: POR CONCEPTO DE: | C11: PRESTACION DE SERVICIOS
A13: Declaro voluntariamente y bajo la gravedad de juramento, que no soy responsable del impuesto del IVA. Declaro que mis ingresos mensuales provienen de la compensación por servicios personales y que para obtenerlos no he contratado ni vinculado dos (2) o más trabajadores asociados a la actividad. Lo anterior con el propósito de ser beneficiario en el cálculo de la retención en la fuente por concepto de honorarios, según lo dispuesto en el art 383 del estatuto tributario.
A21: FIRMA
