Workbook

Sheet A
A1: Yumbo,15 Abril 2025 | E1: Cuenta de Cobro | G1: 23-949
A3: Yo
A4: Con C.C
A5: Manifiesto que: FUNDACION UNA MANO AMIGA A TIEMPO NIT: 901.369.891-9
A9: ME DEBE LA SUMA DE: | C9: 640000
A10: VALOR EN PESOS: | C10: {=UPPER([1]!NumLetra(C9,,"PESOS"))} -> SEISCIENTOS CUARENTA MIL PESOS
A11: POR CONCEPTO DE: | C11: PRESTACION DE SERVICIOS
A13: Declaro voluntariamente y bajo la gravedad de juramento, que no soy responsable del impuesto del IVA. Declaro que mis ingresos mensuales provienen de la compensación por servicios personales y que para obtenerlos no he contratado ni vinculado dos (2) o más trabajadores asociados a la actividad. Lo anterior con el propósito de ser beneficiario en el cálculo de la retención en la fuente por concepto de honorarios, según lo dispuesto en el art 383 del estatuto tributario.
A21: FIRMA
A24: =A1 -> Yumbo,15 Abril 2025 | E24: Cuenta de Cobro | G24: 23-951
A26: Yo | B26: =[2]Hoja1!B10 -> Arredondo Angie Melissa
A27: Con C.C | B27: =[2]Hoja1!A10 -> 1007779358
A28: Manifiesto que: FUNDACION UNA MANO AMIGA A TIEMPO NIT: 901.369.891-9
A32: ME DEBE LA SUMA DE: | C32: 700000
A33: VALOR EN PESOS: | C33: {=UPPER([1]!NumLetra(C32,,"PESOS"))} -> SETECIENTOS MIL PESOS
A34: POR CONCEPTO DE: | C34: PRESTACION DE SERVICIOS
A36: Declaro voluntariamente y bajo la gravedad de juramento, que no soy responsable del impuesto del IVA. Declaro que mis ingresos mensuales provienen de la compensación por servicios personales y que para obtenerlos no he contratado ni vinculado dos (2) o más trabajadores asociados a la actividad. Lo anterior con el propósito de ser beneficiario en el cálculo de la retención en la fuente por concepto de honorarios, según lo dispuesto en el art 383 del estatuto tributario.
A44: FIRMA
A49: =A24 -> Yumbo,15 Abril 2025 | E49: Cuenta de Cobro | G49: 23-986
A51: Yo | B51: Angela Hurtado
A52: Con C.C | B52: 1113630071
A53: Manifiesto que: FUNDACION UNA MANO AMIGA A TIEMPO NIT: 901.369.891-9
A57: ME DEBE LA SUMA DE: | C57: 352500
A58: VALOR EN PESOS: | C58: {=UPPER([1]!NumLetra(C57,,"PESOS"))} -> TRESCIENTOS CINCUENTA Y DOS MIL QUINIENTOS PESOS
A59: POR CONCEPTO DE: | C59: PRESTACION DE SERVICIOS
A61: Declaro voluntariamente y bajo la gravedad de juramento, que no soy responsable del impuesto del IVA. Declaro que mis ingresos mensuales provienen de la compensación por servicios personales y que para obtenerlos no he contratado ni vinculado dos (2) o más trabajadores asociados a la actividad. Lo anterior con el propósito de ser beneficiario en el cálculo de la retención en la fuente por concepto de honorarios, según lo dispuesto en el art 383 del estatuto tributario.
A69: FIRMA
A72: =A49 -> Yumbo,15 Abril 2025 | E72: Cuenta de Cobro | G72: 23-986
A74: Yo | B74: Ana Delina Gomez
A75: Con C.C | B75: 1090473910
A76: Manifiesto que: FUNDACION UNA MANO AMIGA A TIEMPO NIT: 901.369.891-9
A80: ME DEBE LA SUMA DE: | C80: 272000
A81: VALOR EN PESOS: | C81: {=UPPER([1]!NumLetra(C80,,"PESOS"))} -> DOSCIENTOS SETENTA Y DOS MIL PESOS
A82: POR CONCEPTO DE: | C82: PRESTACION DE SERVICIOS
A84: Declaro voluntariamente y bajo la gravedad de juramento, que no soy responsable del impuesto del IVA. Declaro que mis ingresos mensuales provienen de la compensación por servicios personales y que para obtenerlos no he contratado ni vinculado dos (2) o más trabajadores asociados a la actividad. Lo anterior con el propósito de ser beneficiario en el cálculo de la retención en la fuente por concepto de honorarios, según lo dispuesto en el art 383 del estatuto tributario.
A92: FIRMA
A95: =A72 -> Yumbo,15 Abril 2025 | E95: Cuenta de Cobro | G95: 23-986
A97: Yo | B97: Aura Adelfa Alvarez Vinasco
A98: Con C.C | B98: 31469693
A99: Manifiesto que: FUNDACION UNA MANO AMIGA A TIEMPO NIT: 901.369.891-9
...

Sheet B
A1: =A!A1 -> Yumbo,15 Abril 2025 | E1: Cuenta de Cobro | G1: 23-986
A3: Yo | B3: Baleria Orias
A4: Con C.C | B4: 1006287986
A5: Manifiesto que: FUNDACION UNA MANO AMIGA A TIEMPO NIT: 901.369.891-9
A9: ME DEBE LA SUMA DE: | C9: 376000
A10: VALOR EN PESOS: | C10: {=UPPER([1]!NumLetra(C9,,"PESOS"))} -> TRESCIENTOS SETENTA Y SEIS MIL PESOS
A11: POR CONCEPTO DE: | C11: PRESTACION DE SERVICIOS
A13: Declaro voluntariamente y bajo la gravedad de juramento, que no soy responsable del impuesto del IVA. Declaro que mis ingresos mensuales provienen de la compensación por servicios personales y que para obtenerlos no he contratado ni vinculado dos (2) o más trabajadores asociados a la actividad. Lo anterior con el propósito de ser beneficiario en el cálculo de la retención en la fuente por concepto de honorarios, según lo dispuesto en el art 383 del estatuto tributario.
A21: FIRMA

Sheet C
A1: =D!A1 -> Yumbo,15 Abril 2025 | E1: Cuenta de Cobro | G1: 23-974
A3: Yo | B3: ='[3]PLANILLA MATRIX'!$B$72 -> Galarza Carlos Andres
A4: Con C.C | B4: ='[3]PLANILLA MATRIX'!$A$72 -> 16461107
A5: Manifiesto que: FUNDACION UNA MANO AMIGA A TIEMPO NIT: 901.369.891-9
A9: ME DEBE LA SUMA DE: | C9: 297000
A10: VALOR EN PESOS: | C10: {=UPPER([1]!NumLetra(C9,,"PESOS"))} -> DOSCIENTOS NOVENTA Y SIETE MIL PESOS
A11: POR CONCEPTO DE: | C11: PRESTACION DE SERVICIOS
A13: Declaro voluntariamente y bajo la gravedad de juramento, que no soy responsable del impuesto del IVA. Declaro que mis ingresos mensuales provienen de la compensación por servicios personales y que para obtenerlos no he contratado ni vinculado dos (2) o más trabajadores asociados a la actividad. Lo anterior con el propósito de ser beneficiario en el cálculo de la retención en la fuente por concepto de honorarios, según lo dispuesto en el art 383 del estatuto tributario.
A21: FIRMA
A25: =A1 -> Yumbo,15 Abril 2025 | E25: Cuenta de Cobro | G25: 23-978
A27: Yo | B27: =[2]Hoja1!B45 -> Alvarez Gonzales Claudia
A28: Con C.C | B28: =[2]Hoja1!A45 -> 1093214577
A29: Manifiesto que: FUNDACION UNA MANO AMIGA A TIEMPO NIT: 901.369.891-9
A33: ME DEBE LA SUMA DE: | C33: 255000
A34: VALOR EN PESOS: | C34: {=UPPER([1]!NumLetra(C33,,"PESOS"))} -> DOSCIENTOS CINCUENTA Y CINCO MIL PESOS
A35: POR CONCEPTO DE: | C35: PRESTACION DE SERVICIOS
A37: Declaro voluntariamente y bajo la gravedad de juramento, que no soy responsable del impuesto del IVA. Declaro que mis ingresos mensuales provienen de la compensación por servicios personales y que para obtenerlos no he contratado ni vinculado dos (2) o más trabajadores asociados a la actividad. Lo anterior con el propósito de ser beneficiario en el cálculo de la retención en la fuente por concepto de honorarios, según lo dispuesto en el art 383 del estatuto tributario.
A45: FIRMA
A49: =A25 -> Yumbo,15 Abril 2025 | E49: Cuenta de Cobro | G49: 23-977
A51: Yo | B51: Cesar Otero
A52: Con C.C | B52: 1118295605
A53: Manifiesto que: FUNDACION UNA MANO AMIGA A TIEMPO NIT: 901.369.891-9
A57: ME DEBE LA SUMA DE: | C57: 39300
A58: VALOR EN PESOS: | C58: {=UPPER([1]!NumLetra(C57,,"PESOS"))} -> TREINTA Y NUEVE MIL TRESCIENTOS PESOS
A59: POR CONCEPTO DE: | C59: PRESTACION DE SERVICIOS
A61: Declaro voluntariamente y bajo la gravedad de juramento, que no soy responsable del impuesto del IVA. Declaro que mis ingresos mensuales provienen de la compensación por servicios personales y que para obtenerlos no he contratado ni vinculado dos (2) o más trabajadores asociados a la actividad. Lo anterior con el propósito de ser beneficiario en el cálculo de la retención en la fuente por concepto de honorarios, según lo dispuesto en el art 383 del estatuto tributario.
A72: =A49 -> Yumbo,15 Abril 2025 | E72: Cuenta de Cobro | G72: 23-988
A74: Yo | B74: =[2]Hoja1!B58 -> Carlos Andres Ramirez
A75: Con C.C | B75: =[2]Hoja1!A58 -> 16462002
A76: Manifiesto que: FUNDACION UNA MANO AMIGA A TIEMPO NIT: 901.369.891-9
A80: ME DEBE LA SUMA DE: | C80: 257100
A81: VALOR EN PESOS: | C81: {=UPPER([1]!NumLetra(C80,,"PESOS"))} -> DOSCIENTOS CINCUENTA Y SIETE MIL CIEN PESOS
A82: POR CONCEPTO DE: | C82: PRESTACION DE SERVICIOS
A84: Declaro voluntariamente y bajo la gravedad de juramento, que no soy responsable del impuesto del IVA. Declaro que mis ingresos mensuales provienen de la compensación por servicios personales y que para obtenerlos no he contratado ni vinculado dos (2) o más trabajadores asociados a la actividad. Lo anterior con el propósito de ser beneficiario en el cálculo de la retención en la fuente por concepto de honorarios, según lo dispuesto en el art 383 del estatuto tributario.
A92: FIRMA
A96: =A72 -> Yumbo,15 Abril 2025 | E96: Cuenta de Cobro | G96: 23-995
A98: Yo | B98: Cristina Ossa
A99: Con C.C | B99: 31997511
A100: Manifiesto que: FUNDACION UNA MANO AMIGA A TIEMPO NIT: 901.369.891-9
A104: ME DEBE LA SUMA DE: | C104: 170000
...

Sheet D
A1: =A!A1 -> Yumbo,15 Abril 2025 | E1: Cuenta de Cobro
A3: Yo | B3: Diana Carolina Arias
A4: Con C.C | B4: 1007779173
A5: Manifiesto que: FUNDACION UNA MANO AMIGA A TIEMPO NIT: 901.369.891-9
A9: ME DEBE LA SUMA DE: | C9: 322000
A10: VALOR EN PESOS: | C10: {=UPPER([1]!NumLetra(C9,,"PESOS"))} -> TRESCIENTOS VEINTIDOS MIL PESOS
A11: POR CONCEPTO DE: | C11: TURNOS PENDIENTES DE LA 1RA QUINCENA DE ENERO
A13: Declaro voluntariamente y bajo la gravedad de juramento, que no soy responsable del impuesto del IVA. Declaro que mis ingresos mensuales provienen de la compensación por servicios personales y que para obtenerlos no he contratado ni vinculado dos (2) o más trabajadores asociados a la actividad. Lo anterior con el propósito de ser beneficiario en el cálculo de la retención en la fuente por concepto de honorarios, según lo dispuesto en el art 383 del estatuto tributario.
A21: FIRMA
A25: =A1 -> Yumbo,15 Abril 2025 | E25: Cuenta de Cobro | G25: 23-973
A27: Yo | B27: ='[4]PLANILLA MATRIX'!$B$71 -> Diana Lorena Riascos
A28: Con C.C | B28: ='[4]PLANILLA MATRIX'!$A$71 -> 1118290778
A29: Manifiesto que: FUNDACION UNA MANO AMIGA A TIEMPO NIT: 901.369.891-9
A33: ME DEBE LA SUMA DE: | C33: 297000
A34: VALOR EN PESOS: | C34: {=UPPER([1]!NumLetra(C33,,"PESOS"))} -> DOSCIENTOS NOVENTA Y SIETE MIL PESOS
A35: POR CONCEPTO DE: | C35: PRESTACION DE SERVICIOS
A37: Declaro voluntariamente y bajo la gravedad de juramento, que no soy responsable del impuesto del IVA. Declaro que mis ingresos mensuales provienen de la compensación por servicios personales y que para obtenerlos no he contratado ni vinculado dos (2) o más trabajadores asociados a la actividad. Lo anterior con el propósito de ser beneficiario en el cálculo de la retención en la fuente por concepto de honorarios, según lo dispuesto en el art 383 del estatuto tributario.
A45: FIRMA
A49: =A1 -> Yumbo,15 Abril 2025 | E49: Cuenta de Cobro | G49: 23-975
A51: Yo | B51: Darly Julieth Alvares
A52: Con C.C | B52: 1118284277
A53: Manifiesto que: FUNDACION UNA MANO AMIGA A TIEMPO NIT: 901.369.891-9
A57: ME DEBE LA SUMA DE: | C57: 409000
A58: VALOR EN PESOS: | C58: {=UPPER([1]!NumLetra(C57,,"PESOS"))} -> CUATROCIENTOS NUEVE MIL PESOS
A59: POR CONCEPTO DE: | C59: PRESTACION DE SERVICIOS
A61: Declaro voluntariamente y bajo la gravedad de juramento, que no soy responsable del impuesto del IVA. Declaro que mis ingresos mensuales provienen de la compensación por servicios personales y que para obtenerlos no he contratado ni vinculado dos (2) o más trabajadores asociados a la actividad. Lo anterior con el propósito de ser beneficiario en el cálculo de la retención en la fuente por concepto de honorarios, según lo dispuesto en el art 383 del estatuto tributario.
A69: FIRMA
A73: =A49 -> Yumbo,15 Abril 2025 | E73: Cuenta de Cobro | G73: 23-982
A75: Yo | B75: =[2]Hoja1!B64 -> Garzon Donella
A76: Con C.C | B76: =[2]Hoja1!A64 -> 29939491
A77: Manifiesto que: FUNDACION UNA MANO AMIGA A TIEMPO NIT: 901.369.891-9
A81: ME DEBE LA SUMA DE: | C81: 434000
A82: VALOR EN PESOS: | C82: {=UPPER([1]!NumLetra(C81,,"PESOS"))} -> CUATROCIENTOS TREINTA Y CUATRO MIL PESOS
A83: POR CONCEPTO DE: | C83: PRESTACION DE SERVICIOS
A85: Declaro voluntariamente y bajo la gravedad de juramento, que no soy responsable del impuesto del IVA. Declaro que mis ingresos mensuales provienen de la compensación por servicios personales y que para obtenerlos no he contratado ni vinculado dos (2) o más trabajadores asociados a la actividad. Lo anterior con el propósito de ser beneficiario en el cálculo de la retención en la fuente por concepto de honorarios, según lo dispuesto en el art 383 del estatuto tributario.
A93: FIRMA
A97: =A73 -> Yumbo,15 Abril 2025 | E97: Cuenta de Cobro | G97: 23-982
A99: Yo | B99: Diego Armando Osorio
A100: Con C.C | B100: 1118301750
A101: Manifiesto que: FUNDACION UNA MANO AMIGA A TIEMPO NIT: 901.369.891-9
...

Sheet E
A1: =A!A24 -> Yumbo,15 Abril 2025 | E1: Cuenta de Cobro | G1: 23-949
A3: Yo | B3: =[2]Hoja1!B7 -> Garzon Eloisa
A4: Con C.C | B4: =[2]Hoja1!A7 -> 31483643
A5: Manifiesto que: FUNDACION UNA MANO AMIGA A TIEMPO NIT: 901.369.891-9
A9: ME DEBE LA SUMA DE: | C9: 690000
A10: VALOR EN PESOS: | C10: {=UPPER([1]!NumLetra(C9,,"PESOS"))} -> SEISCIENTOS NOVENTA MIL PESOS
A11: POR CONCEPTO DE: | C11: PRESTACION DE SERVICIOS
A13: Declaro voluntariamente y bajo la gravedad de juramento, que no soy responsable del impuesto del IVA. Declaro que mis ingresos mensuales provienen de la compensación por servicios personales y que para obtenerlos no he contratado ni vinculado dos (2) o más trabajadores asociados a la actividad. Lo anterior con el propósito de ser beneficiario en el cálculo de la retención en la fuente por concepto de honorarios, según lo dispuesto en el art 383 del estatuto tributario.
A21: FIRMA
A25: =E!A1 -> Yumbo,15 Abril 2025 | E25: Cuenta de Cobro | G25: 23-962
A27: Yo | B27: Eider Pabon
A28: Con C.C | B28: 16453190
A29: Manifiesto que: FUNDACION UNA MANO AMIGA A TIEMPO NIT: 901.369.891-9
A33: ME DEBE LA SUMA DE: | C33: 322000
A34: VALOR EN PESOS: | C34: {=UPPER([1]!NumLetra(C33,,"PESOS"))} -> TRESCIENTOS VEINTIDOS MIL PESOS
A35: POR CONCEPTO DE: | C35: PRESTACION DE SERVICIOS
A37: Declaro voluntariamente y bajo la gravedad de juramento, que no soy responsable del impuesto del IVA. Declaro que mis ingresos mensuales provienen de la compensación por servicios personales y que para obtenerlos no he contratado ni vinculado dos (2) o más trabajadores asociados a la actividad. Lo anterior con el propósito de ser beneficiario en el cálculo de la retención en la fuente por concepto de honorarios, según lo dispuesto en el art 383 del estatuto tributario.
A45: FIRMA
A48: =A72 -> Yumbo,15 Abril 2025 | E48: Cuenta de Cobro | G48: 23-959
A50: Yo | B50: Arias Esteban Alejandro
A51: Con C.C | B51: 1006072723
A52: Manifiesto que: FUNDACION UNA MANO AMIGA A TIEMPO NIT: 901.369.891-9
A56: ME DEBE LA SUMA DE: | C56: 280000
A57: VALOR EN PESOS: | C57: {=UPPER([1]!NumLetra(C56,,"PESOS"))} -> DOSCIENTOS OCHENTA MIL PESOS
A58: POR CONCEPTO DE: | C58: PRESTACION DE SERVICIOS
A60: Declaro voluntariamente y bajo la gravedad de juramento, que no soy responsable del impuesto del IVA. Declaro que mis ingresos mensuales provienen de la compensación por servicios personales y que para obtenerlos no he contratado ni vinculado dos (2) o más trabajadores asociados a la actividad. Lo anterior con el propósito de ser beneficiario en el cálculo de la retención en la fuente por concepto de honorarios, según lo dispuesto en el art 383 del estatuto tributario.
A68: FIRMA
A72: =A95 -> Yumbo,15 Abril 2025 | E72: Cuenta de Cobro | G72: 23-993
A74: Yo | B74: =[2]Hoja1!B81 -> Mayorga Emilce
A75: Con C.C | B75: =[2]Hoja1!A81 -> 1114727110
A76: Manifiesto que: FUNDACION UNA MANO AMIGA A TIEMPO NIT: 901.369.891-9
A80: ME DEBE LA SUMA DE: | C80: 315000
A81: VALOR EN PESOS: | C81: {=UPPER([1]!NumLetra(C80,,"PESOS"))} -> TRESCIENTOS QUINCE MIL PESOS
A82: POR CONCEPTO DE: | C82: PRESTACION DE SERVICIOS
A84: Declaro voluntariamente y bajo la gravedad de juramento, que no soy responsable del impuesto del IVA. Declaro que mis ingresos mensuales provienen de la compensación por servicios personales y que para obtenerlos no he contratado ni vinculado dos (2) o más trabajadores asociados a la actividad. Lo anterior con el propósito de ser beneficiario en el cálculo de la retención en la fuente por concepto de honorarios, según lo dispuesto en el art 383 del estatuto tributario.
A91: FIRMA
A95: =T!A1 -> Yumbo,15 Abril 2025 | E95: Cuenta de Cobro | G95: 23-995
A97: Yo | B97: Emy Gisella Maya
A98: Con C.C | B98: 1110292836
A99: Manifiesto que: FUNDACION UNA MANO AMIGA A TIEMPO NIT: 901.369.891-9
...

Sheet F
A1: =E!A1 -> Yumbo,15 Abril 2025 | E1: Cuenta de Cobro | G1: 23-994
A3: Yo | B3: =[2]Hoja1!B82 -> Ospina Fredy Antonio
A4: Con C.C | B4: =[2]Hoja1!A82 -> 94404511
A5: Manifiesto que: FUNDACION UNA MANO AMIGA A TIEMPO NIT: 901.369.891-9
A9: ME DEBE LA SUMA DE: | C9: 322000
A10: VALOR EN PESOS: | C10: {=UPPER([1]!NumLetra(C9,,"PESOS"))} -> TRESCIENTOS VEINTIDOS MIL PESOS
A11: POR CONCEPTO DE: | C11: PRESTACION DE SERVICIOS
A13: Declaro voluntariamente y bajo la gravedad de juramento, que no soy responsable del impuesto del IVA. Declaro que mis ingresos mensuales provienen de la compensación por servicios personales y que para obtenerlos no he contratado ni vinculado dos (2) o más trabajadores asociados a la actividad. Lo anterior con el propósito de ser beneficiario en el cálculo de la retención en la fuente por concepto de honorarios, según lo dispuesto en el art 383 del estatuto tributario.
A21: FIRMA
A23: =A1 -> Yumbo,15 Abril 2025 | E23: Cuenta de Cobro | G23: 23-994
A25: Yo | B25: Fabiola Aleman
A26: Con C.C | B26: 7257376
A27: Manifiesto que: FUNDACION UNA MANO AMIGA A TIEMPO NIT: 901.369.891-9
A31: ME DEBE LA SUMA DE: | C31: 119000
A32: VALOR EN PESOS: | C32: {=UPPER([1]!NumLetra(C31,,"PESOS"))} -> CIENTO DIECINUEVE MIL PESOS
A33: POR CONCEPTO DE: | C33: PRESTACION DE SERVICIOS
A35: Declaro voluntariamente y bajo la gravedad de juramento, que no soy responsable del impuesto del IVA. Declaro que mis ingresos mensuales provienen de la compensación por servicios personales y que para obtenerlos no he contratado ni vinculado dos (2) o más trabajadores asociados a la actividad. Lo anterior con el propósito de ser beneficiario en el cálculo de la retención en la fuente por concepto de honorarios, según lo dispuesto en el art 383 del estatuto tributario.
A43: FIRMA

Sheet G
A1: Yumbo, 28 febrero 2025 | E1: Cuenta de Cobro | G1: 23-963
A3: Yo | B3: ='[5]PLANILLA MATRIX'!$B$32 -> Dominguez Guillermo
A4: Con C.C | B4: ='[5]PLANILLA MATRIX'!$A$32 -> 16461820
A5: Manifiesto que: FUNDACION UNA MANO AMIGA A TIEMPO NIT: 901.369.891-9
A9: ME DEBE LA SUMA DE: | C9: 297000
A10: VALOR EN PESOS: | C10: {=UPPER([1]!NumLetra(C9,,"PESOS"))} -> DOSCIENTOS NOVENTA Y SIETE MIL PESOS
A11: POR CONCEPTO DE: | C11: PRESTACION DE SERVICIOS
A13: Declaro voluntariamente y bajo la gravedad de juramento, que no soy responsable del impuesto del IVA. Declaro que mis ingresos mensuales provienen de la compensación por servicios personales y que para obtenerlos no he contratado ni vinculado dos (2) o más trabajadores asociados a la actividad. Lo anterior con el propósito de ser beneficiario en el cálculo de la retención en la fuente por concepto de honorarios, según lo dispuesto en el art 383 del estatuto tributario.
A21: FIRMA
A25: =A1 -> Yumbo, 28 febrero 2025 | E25: Cuenta de Cobro | G25: 23-975
A27: Yo | B27: Gildardo Emilio Moscoso
A28: Con C.C | B28: 7510791
A29: Manifiesto que: FUNDACION UNA MANO AMIGA A TIEMPO NIT: 901.369.891-9
A33: ME DEBE LA SUMA DE: | C33: 393000
A34: VALOR EN PESOS: | C34: {=UPPER([1]!NumLetra(C33,,"PESOS"))} -> TRESCIENTOS NOVENTA Y TRES MIL PESOS
A35: POR CONCEPTO DE: | C35: PRESTACION DE SERVICIOS
A37: Declaro voluntariamente y bajo la gravedad de juramento, que no soy responsable del impuesto del IVA. Declaro que mis ingresos mensuales provienen de la compensación por servicios personales y que para obtenerlos no he contratado ni vinculado dos (2) o más trabajadores asociados a la actividad. Lo anterior con el propósito de ser beneficiario en el cálculo de la retención en la fuente por concepto de honorarios, según lo dispuesto en el art 383 del estatuto tributario.
A45: FIRMA
A49: =A!A95 -> Yumbo,15 Abril 2025 | E49: Cuenta de Cobro | G49: 23-979
A51: Yo | B51: =[2]Hoja1!B47 -> Gloria Teresa Urbano
A52: Con C.C | B52: =[2]Hoja1!A47 -> 66808176
A53: Manifiesto que: FUNDACION UNA MANO AMIGA A TIEMPO NIT: 901.369.891-9
A57: ME DEBE LA SUMA DE: | C57: 322000
A58: VALOR EN PESOS: | C58: {=UPPER([1]!NumLetra(C57,,"PESOS"))} -> TRESCIENTOS VEINTIDOS MIL PESOS
A59: POR CONCEPTO DE: | C59: PRESTACION DE SERVICIOS
A61: Declaro voluntariamente y bajo la gravedad de juramento, que no soy responsable del impuesto del IVA. Declaro que mis ingresos mensuales provienen de la compensación por servicios personales y que para obtenerlos no he contratado ni vinculado dos (2) o más trabajadores asociados a la actividad. Lo anterior con el propósito de ser beneficiario en el cálculo de la retención en la fuente por concepto de honorarios, según lo dispuesto en el art 383 del estatuto tributario.
A69: FIRMA

Sheet H

Sheet I
A1: =M!A167 -> Yumbo,15 Abril 2025 | E1: Cuenta de Cobro | G1: 23-995
A3: Yo | B3: Isabella Bermudez
A4: Con C.C | B4: 1107642330
A5: Manifiesto que: FUNDACION UNA MANO AMIGA A TIEMPO NIT: 901.369.891-9
A9: ME DEBE LA SUMA DE: | C9: 255000
A10: VALOR EN PESOS: | C10: {=UPPER([1]!NumLetra(C9,,"PESOS"))} -> DOSCIENTOS CINCUENTA Y CINCO MIL PESOS
A11: POR CONCEPTO DE: | C11: PRESTACION SERVICIOS
A13: Declaro voluntariamente y bajo la gravedad de juramento, que no soy responsable del impuesto del IVA. Declaro que mis ingresos mensuales provienen de la compensación por servicios personales y que para obtenerlos no he contratado ni vinculado dos (2) o más trabajadores asociados a la actividad. Lo anterior con el propósito de ser beneficiario en el cálculo de la retención en la fuente por concepto de honorarios, según lo dispuesto en el art 383 del estatuto tributario.
A20: FIRMA

Sheet J
A1: =A!A1 -> Yumbo,15 Abril 2025 | E1: Cuenta de Cobro | G1: 23-951
A3: Yo | B3: Johana Garzon
A4: Con C.C | B4: 31485571
A5: Manifiesto que: FUNDACION UNA MANO AMIGA A TIEMPO NIT: 901.369.891-9
A9: ME DEBE LA SUMA DE: | C9: 32100
A10: VALOR EN PESOS: | C10: {=UPPER([1]!NumLetra(C9,,"PESOS"))} -> TREINTA Y DOS MIL CIEN PESOS
A11: POR CONCEPTO DE: | C11: PRESTACION DE SERVICIOS
A13: Declaro voluntariamente y bajo la gravedad de juramento, que no soy responsable del impuesto del IVA. Declaro que mis ingresos mensuales provienen de la compensación por servicios personales y que para obtenerlos no he contratado ni vinculado dos (2) o más trabajadores asociados a la actividad. Lo anterior con el propósito de ser beneficiario en el cálculo de la retención en la fuente por concepto de honorarios, según lo dispuesto en el art 383 del estatuto tributario.
A21: FIRMA
A25: =A49 -> Yumbo,15 Abril 2025 | E25: Cuenta de Cobro | G25: 23-953
A27: Yo | B27: Arcila Gil Juan Alquiber
A28: Con C.C | B28: 94253614
A29: Manifiesto que: FUNDACION UNA MANO AMIGA A TIEMPO NIT: 901.369.891-9
A33: ME DEBE LA SUMA DE: | C33: 482000
A34: VALOR EN PESOS: | C34: {=UPPER([1]!NumLetra(C33,,"PESOS"))} -> CUATROCIENTOS OCHENTA Y DOS MIL PESOS
A35: POR CONCEPTO DE: | C35: PRESTACION DE SERVICIOS
A37: Declaro voluntariamente y bajo la gravedad de juramento, que no soy responsable del impuesto del IVA. Declaro que mis ingresos mensuales provienen de la compensación por servicios personales y que para obtenerlos no he contratado ni vinculado dos (2) o más trabajadores asociados a la actividad. Lo anterior con el propósito de ser beneficiario en el cálculo de la retención en la fuente por concepto de honorarios, según lo dispuesto en el art 383 del estatuto tributario.
A45: FIRMA
A49: =A!A1 -> Yumbo,15 Abril 2025 | E49: Cuenta de Cobro | G49: 23-958
A51: Yo | B51: ='[6]PLANILLA MATRIX'!$B$28 -> Granada Jhoan Sebastian
A52: Con C.C | B52: 118306042
A53: Manifiesto que: FUNDACION UNA MANO AMIGA A TIEMPO NIT: 901.369.891-9
A57: ME DEBE LA SUMA DE: | C57: 322000
A58: VALOR EN PESOS: | C58: {=UPPER([1]!NumLetra(C57,,"PESOS"))} -> TRESCIENTOS VEINTIDOS MIL PESOS
A59: POR CONCEPTO DE: | C59: PRESTACION DE SERVICIOS
A61: Declaro voluntariamente y bajo la gravedad de juramento, que no soy responsable del impuesto del IVA. Declaro que mis ingresos mensuales provienen de la compensación por servicios personales y que para obtenerlos no he contratado ni vinculado dos (2) o más trabajadores asociados a la actividad. Lo anterior con el propósito de ser beneficiario en el cálculo de la retención en la fuente por concepto de honorarios, según lo dispuesto en el art 383 del estatuto tributario.
A69: FIRMA
A73: =E!A1 -> Yumbo,15 Abril 2025 | E73: Cuenta de Cobro | G73: 23-962
A75: Yo | B75: Johan Esteban Cabrera
A76: Con C.C | B76: 1109184541
A77: Manifiesto que: FUNDACION UNA MANO AMIGA A TIEMPO NIT: 901.369.891-9
A81: ME DEBE LA SUMA DE: | C81: 30000
A82: VALOR EN PESOS: | C82: {=UPPER([1]!NumLetra(C81,,"PESOS"))} -> TREINTA MIL PESOS
A83: POR CONCEPTO DE: | C83: PRESTACION DE SERVICIOS
A85: Declaro voluntariamente y bajo la gravedad de juramento, que no soy responsable del impuesto del IVA. Declaro que mis ingresos mensuales provienen de la compensación por servicios personales y que para obtenerlos no he contratado ni vinculado dos (2) o más trabajadores asociados a la actividad. Lo anterior con el propósito de ser beneficiario en el cálculo de la retención en la fuente por concepto de honorarios, según lo dispuesto en el art 383 del estatuto tributario.
A93: FIRMA
A96: =E!A1 -> Yumbo,15 Abril 2025 | E96: Cuenta de Cobro | G96: 23-951
A98: Yo | B98: Jenny Andrea Osorio
A99: Con C.C | B99: 40627634
A100: Manifiesto que: FUNDACION UNA MANO AMIGA A TIEMPO NIT: 901.369.891-9
...

Sheet K
A1: =A!A24 -> Yumbo,15 Abril 2025 | E1: Cuenta de Cobro | G1: 23-997
A3: Yo | B3: Karen Tatiana Bravo
A4: Con C.C | B4: 1063722921
A5: Manifiesto que: FUNDACION UNA MANO AMIGA A TIEMPO NIT: 901.369.891-9
A9: ME DEBE LA SUMA DE: | C9: 300000
A10: VALOR EN PESOS: | C10: {=UPPER([1]!NumLetra(C9,,"PESOS"))} -> TRESCIENTOS MIL PESOS
A11: POR CONCEPTO DE: | C11: TURNOS PENDIENTES DE LA 1RA QUINCENA DE ENERO
A13: Declaro voluntariamente y bajo la gravedad de juramento, que no soy responsable del impuesto del IVA. Declaro que mis ingresos mensuales provienen de la compensación por servicios personales y que para obtenerlos no he contratado ni vinculado dos (2) o más trabajadores asociados a la actividad. Lo anterior con el propósito de ser beneficiario en el cálculo de la retención en la fuente por concepto de honorarios, según lo dispuesto en el art 383 del estatuto tributario.
A20: FIRMA
A24: =A1 -> Yumbo,15 Abril 2025 | E24: Cuenta de Cobro | G24: 23-997
A26: Yo | B26: Karen Marcela Perez Nieva
A27: Con C.C | B27: 1236438574
A28: Manifiesto que: FUNDACION UNA MANO AMIGA A TIEMPO NIT: 901.369.891-9
A32: ME DEBE LA SUMA DE: | C32: 39300
A33: VALOR EN PESOS: | C33: {=UPPER([1]!NumLetra(C32,,"PESOS"))} -> TREINTA Y NUEVE MIL TRESCIENTOS PESOS
A34: POR CONCEPTO DE: | C34: TURNOS PENDIENTES DE LA 1RA QUINCENA DE ENERO
A36: Declaro voluntariamente y bajo la gravedad de juramento, que no soy responsable del impuesto del IVA. Declaro que mis ingresos mensuales provienen de la compensación por servicios personales y que para obtenerlos no he contratado ni vinculado dos (2) o más trabajadores asociados a la actividad. Lo anterior con el propósito de ser beneficiario en el cálculo de la retención en la fuente por concepto de honorarios, según lo dispuesto en el art 383 del estatuto tributario.
A43: FIRMA

Sheet L
A1: =E!A1 -> Yumbo,15 Abril 2025 | E1: Cuenta de Cobro | G1: 23-987
A3: Yo | B3: =[2]Hoja1!B57 -> Suarez Luis Carlos
A4: Con C.C | B4: =[2]Hoja1!A57 -> 16454804
A5: Manifiesto que: FUNDACION UNA MANO AMIGA A TIEMPO NIT: 901.369.891-9
A9: ME DEBE LA SUMA DE: | C9: 221000
A10: VALOR EN PESOS: | C10: {=UPPER([1]!NumLetra(C9,,"PESOS"))} -> DOSCIENTOS VEINTIUN MIL PESOS
A11: POR CONCEPTO DE: | C11: PRESTACION DE SERVICIOS
A13: Declaro voluntariamente y bajo la gravedad de juramento, que no soy responsable del impuesto del IVA. Declaro que mis ingresos mensuales provienen de la compensación por servicios personales y que para obtenerlos no he contratado ni vinculado dos (2) o más trabajadores asociados a la actividad. Lo anterior con el propósito de ser beneficiario en el cálculo de la retención en la fuente por concepto de honorarios, según lo dispuesto en el art 383 del estatuto tributario.
A21: FIRMA
A26: =E!A1 -> Yumbo,15 Abril 2025 | E26: Cuenta de Cobro | G26: 23-964
A28: Yo | B28: Luz Albany Quiceno
A29: Con C.C | B29: 66981845
A30: Manifiesto que: FUNDACION UNA MANO AMIGA A TIEMPO NIT: 901.369.891-9
A34: ME DEBE LA SUMA DE: | C34: 80000
A35: VALOR EN PESOS: | C35: {=UPPER([1]!NumLetra(C34,,"PESOS"))} -> OCHENTA MIL PESOS
A36: POR CONCEPTO DE: | C36: PRESTACION DE SERVICIOS
A38: Declaro voluntariamente y bajo la gravedad de juramento, que no soy responsable del impuesto del IVA. Declaro que mis ingresos mensuales provienen de la compensación por servicios personales y que para obtenerlos no he contratado ni vinculado dos (2) o más trabajadores asociados a la actividad. Lo anterior con el propósito de ser beneficiario en el cálculo de la retención en la fuente por concepto de honorarios, según lo dispuesto en el art 383 del estatuto tributario.
A46: FIRMA
A50: =I!A1 -> Yumbo,15 Abril 2025 | E50: Cuenta de Cobro | G50: 23-995
A52: Yo | B52: Luz Elia Salazar
A53: Con C.C | B53: 31483739
A54: Manifiesto que: FUNDACION UNA MANO AMIGA A TIEMPO NIT: 901.369.891-9
A58: ME DEBE LA SUMA DE: | C58: 272000
A59: VALOR EN PESOS: | C59: {=UPPER([1]!NumLetra(C58,,"PESOS"))} -> DOSCIENTOS SETENTA Y DOS MIL PESOS
A60: POR CONCEPTO DE: | C60: PRESTACION SERVICIOS
A62: Declaro voluntariamente y bajo la gravedad de juramento, que no soy responsable del impuesto del IVA. Declaro que mis ingresos mensuales provienen de la compensación por servicios personales y que para obtenerlos no he contratado ni vinculado dos (2) o más trabajadores asociados a la actividad. Lo anterior con el propósito de ser beneficiario en el cálculo de la retención en la fuente por concepto de honorarios, según lo dispuesto en el art 383 del estatuto tributario.
A69: FIRMA
A72: =A50 -> Yumbo,15 Abril 2025 | E72: Cuenta de Cobro | G72: 23-995
A74: Yo | B74: Lino Calero
A75: Con C.C | B75: 16448514
A76: Manifiesto que: FUNDACION UNA MANO AMIGA A TIEMPO NIT: 901.369.891-9
A80: ME DEBE LA SUMA DE: | C80: 418000
A81: VALOR EN PESOS: | C81: {=UPPER([1]!NumLetra(C80,,"PESOS"))} -> CUATROCIENTOS DIECIOCHO MIL PESOS
A82: POR CONCEPTO DE: | C82: PRESTACION SERVICIOS
A84: Declaro voluntariamente y bajo la gravedad de juramento, que no soy responsable del impuesto del IVA. Declaro que mis ingresos mensuales provienen de la compensación por servicios personales y que para obtenerlos no he contratado ni vinculado dos (2) o más trabajadores asociados a la actividad. Lo anterior con el propósito de ser beneficiario en el cálculo de la retención en la fuente por concepto de honorarios, según lo dispuesto en el art 383 del estatuto tributario.
A91: FIRMA
A94: =A72 -> Yumbo,15 Abril 2025 | E94: Cuenta de Cobro | G94: 23-995
A96: Yo | B96: Luis Alberto Morales Calvo
A97: Con C.C | B97: 16448514
A98: Manifiesto que: FUNDACION UNA MANO AMIGA A TIEMPO NIT: 901.369.891-9
...

Sheet M
A1: =A25 -> Yumbo,15 Abril 2025 | E1: Cuenta de Cobro | G1: 23-950
A3: Yo | B3: Mildred Alexandra Llanten Fernandez
A4: Con C.C | B4: 1118295832
A5: Manifiesto que: FUNDACION UNA MANO AMIGA A TIEMPO NIT: 901.369.891-9
A9: ME DEBE LA SUMA DE: | C9: 322000
A10: VALOR EN PESOS: | C10: {=UPPER([1]!NumLetra(C9,,"PESOS"))} -> TRESCIENTOS VEINTIDOS MIL PESOS
A11: POR CONCEPTO DE: | C11: PRESTACION DE SERVICIOS
A13: Declaro voluntariamente y bajo la gravedad de juramento, que no soy responsable del impuesto del IVA. Declaro que mis ingresos mensuales provienen de la compensación por servicios personales y que para obtenerlos no he contratado ni vinculado dos (2) o más trabajadores asociados a la actividad. Lo anterior con el propósito de ser beneficiario en el cálculo de la retención en la fuente por concepto de honorarios, según lo dispuesto en el art 383 del estatuto tributario.
A21: FIRMA
A25: =A!A1 -> Yumbo,15 Abril 2025 | E25: Cuenta de Cobro | G25: 23-951
A27: Yo | B27: ='[8]PLANILLA MATRIX'!$B$10 -> Maria Cielo Salazar
A28: Con C.C | B28: ='[8]PLANILLA MATRIX'!$A$10 -> 31475396
A29: Manifiesto que: FUNDACION UNA MANO AMIGA A TIEMPO NIT: 901.369.891-9
A33: ME DEBE LA SUMA DE: | C33: 34000
A34: VALOR EN PESOS: | C34: {=UPPER([1]!NumLetra(C33,,"PESOS"))} -> TREINTA Y CUATRO MIL PESOS
A35: POR CONCEPTO DE: | C35: PRESTACION DE SERVICIOS
A37: Declaro voluntariamente y bajo la gravedad de juramento, que no soy responsable del impuesto del IVA. Declaro que mis ingresos mensuales provienen de la compensación por servicios personales y que para obtenerlos no he contratado ni vinculado dos (2) o más trabajadores asociados a la actividad. Lo anterior con el propósito de ser beneficiario en el cálculo de la retención en la fuente por concepto de honorarios, según lo dispuesto en el art 383 del estatuto tributario.
A45: FIRMA
A49: =E!A1 -> Yumbo,15 Abril 2025 | E49: Cuenta de Cobro | G49: 23-986
A51: Yo | B51: Marlon Celis
A52: Con C.C | B52: 1006373793
A53: Manifiesto que: FUNDACION UNA MANO AMIGA A TIEMPO NIT: 901.369.891-9
A57: ME DEBE LA SUMA DE: | C57: 255000
A58: VALOR EN PESOS: | C58: {=UPPER([1]!NumLetra(C57,,"PESOS"))} -> DOSCIENTOS CINCUENTA Y CINCO MIL PESOS
A59: POR CONCEPTO DE: | C59: PRESTACION DE SERVICIOS
A61: Declaro voluntariamente y bajo la gravedad de juramento, que no soy responsable del impuesto del IVA. Declaro que mis ingresos mensuales provienen de la compensación por servicios personales y que para obtenerlos no he contratado ni vinculado dos (2) o más trabajadores asociados a la actividad. Lo anterior con el propósito de ser beneficiario en el cálculo de la retención en la fuente por concepto de honorarios, según lo dispuesto en el art 383 del estatuto tributario.
A69: FIRMA
A73: =A96 -> Yumbo,15 Abril 2025 | E73: Cuenta de Cobro | G73: 23-986
A75: Yo | B75: Mauren Carvajal
A76: Con C.C | B76: 31478979
A77: Manifiesto que: FUNDACION UNA MANO AMIGA A TIEMPO NIT: 901.369.891-9
A81: ME DEBE LA SUMA DE: | C81: 56600
A82: VALOR EN PESOS: | C82: {=UPPER([1]!NumLetra(C81,,"PESOS"))} -> CINCUENTA Y SEIS MIL SEISCIENTOS PESOS
A83: POR CONCEPTO DE: | C83: PRESTACION DE SERVICIOS
A85: Declaro voluntariamente y bajo la gravedad de juramento, que no soy responsable del impuesto del IVA. Declaro que mis ingresos mensuales provienen de la compensación por servicios personales y que para obtenerlos no he contratado ni vinculado dos (2) o más trabajadores asociados a la actividad. Lo anterior con el propósito de ser beneficiario en el cálculo de la retención en la fuente por concepto de honorarios, según lo dispuesto en el art 383 del estatuto tributario.
A93: FIRMA
A96: =A144 -> Yumbo,15 Abril 2025 | E96: Cuenta de Cobro | G96: 23-977
A98: Yo | B98: Maria Fernanda Naspusil
A99: Con C.C | B99: 1118291632
A100: Manifiesto que: FUNDACION UNA MANO AMIGA A TIEMPO NIT: 901.369.891-9
...

Sheet N
A1: =L!A72 -> Yumbo,15 Abril 2025 | E1: Cuenta de Cobro | G1: 23-961
A3: Yo | B3: ='[9]PLANILLA MATRIX'!$B$28 -> Noe Contreras
A4: Con C.C | B4: ='[9]PLANILLA MATRIX'!$A$28 -> 1118291407
A5: Manifiesto que: FUNDACION UNA MANO AMIGA A TIEMPO NIT: 901.369.891-9
A9: ME DEBE LA SUMA DE: | C9: 594000
A10: VALOR EN PESOS: | C10: {=UPPER([1]!NumLetra(C9,,"PESOS"))} -> QUINIENTOS NOVENTA Y CUATRO MIL PESOS
A11: POR CONCEPTO DE: | C11: PRESTACION DE SERVICIOS
A13: Declaro voluntariamente y bajo la gravedad de juramento, que no soy responsable del impuesto del IVA. Declaro que mis ingresos mensuales provienen de la compensación por servicios personales y que para obtenerlos no he contratado ni vinculado dos (2) o más trabajadores asociados a la actividad. Lo anterior con el propósito de ser beneficiario en el cálculo de la retención en la fuente por concepto de honorarios, según lo dispuesto en el art 383 del estatuto tributario.
A21: FIRMA
A24: =M!A73 -> Yumbo,15 Abril 2025 | E24: Cuenta de Cobro | G24: 23-961
A26: Yo | B26: Nataly Vanessa Cuellar Valderram
A27: Con C.C | B27: 1107640759
A28: Manifiesto que: FUNDACION UNA MANO AMIGA A TIEMPO NIT: 901.369.891-9
A32: ME DEBE LA SUMA DE: | C32: 30200
A33: VALOR EN PESOS: | C33: {=UPPER([1]!NumLetra(C32,,"PESOS"))} -> TREINTA MIL DOSCIENTOS PESOS
A34: POR CONCEPTO DE: | C34: PRESTACION DE SERVICIOS
A36: Declaro voluntariamente y bajo la gravedad de juramento, que no soy responsable del impuesto del IVA. Declaro que mis ingresos mensuales provienen de la compensación por servicios personales y que para obtenerlos no he contratado ni vinculado dos (2) o más trabajadores asociados a la actividad. Lo anterior con el propósito de ser beneficiario en el cálculo de la retención en la fuente por concepto de honorarios, según lo dispuesto en el art 383 del estatuto tributario.
A44: FIRMA

Sheet O
A1: =M!A189 -> Yumbo,15 Abril 2025 | E1: Cuenta de Cobro | G1: 23-984
A3: Yo | B3: =[2]Hoja1!B66 -> Aragon Cuartas Onney
A4: Con C.C | B4: =[2]Hoja1!A66 -> 16269074
A5: Manifiesto que: FUNDACION UNA MANO AMIGA A TIEMPO NIT: 901.369.891-9
A9: ME DEBE LA SUMA DE: | C9: 401000
A10: VALOR EN PESOS: | C10: {=UPPER([1]!NumLetra(C9,,"PESOS"))} -> CUATROCIENTOS UN MIL PESOS
A11: POR CONCEPTO DE: | C11: PRESTACION DE SERVICIOS
A13: Declaro voluntariamente y bajo la gravedad de juramento, que no soy responsable del impuesto del IVA. Declaro que mis ingresos mensuales provienen de la compensación por servicios personales y que para obtenerlos no he contratado ni vinculado dos (2) o más trabajadores asociados a la actividad. Lo anterior con el propósito de ser beneficiario en el cálculo de la retención en la fuente por concepto de honorarios, según lo dispuesto en el art 383 del estatuto tributario.
A21: FIRMA

Sheet P
A1: =M!A189 -> Yumbo,15 Abril 2025 | E1: Cuenta de Cobro | G1: 23-977
A3: Yo | B3: Parmenides Noreña
A4: Con C.C | B4: 16590651
A5: Manifiesto que: FUNDACION UNA MANO AMIGA A TIEMPO NIT: 901.369.891-9
A9: ME DEBE LA SUMA DE: | C9: 297000
A10: VALOR EN PESOS: | C10: {=UPPER([1]!NumLetra(C9,,"PESOS"))} -> DOSCIENTOS NOVENTA Y SIETE MIL PESOS
A11: POR CONCEPTO DE: | C11: PRESTACION DE SERVICIOS
A13: Declaro voluntariamente y bajo la gravedad de juramento, que no soy responsable del impuesto del IVA. Declaro que mis ingresos mensuales provienen de la compensación por servicios personales y que para obtenerlos no he contratado ni vinculado dos (2) o más trabajadores asociados a la actividad. Lo anterior con el propósito de ser beneficiario en el cálculo de la retención en la fuente por concepto de honorarios, según lo dispuesto en el art 383 del estatuto tributario.
A20: FIRMA
A25: =A1 -> Yumbo,15 Abril 2025 | E25: Cuenta de Cobro | G25: 23-977
A27: Yo | B27: Parmenides Noreña
A28: Con C.C | B28: 16590651
A29: Manifiesto que: FUNDACION UNA MANO AMIGA A TIEMPO NIT: 901.369.891-9
A33: ME DEBE LA SUMA DE: | C33: 297000
A34: VALOR EN PESOS: | C34: {=UPPER([1]!NumLetra(C33,,"PESOS"))} -> DOSCIENTOS NOVENTA Y SIETE MIL PESOS
A35: POR CONCEPTO DE: | C35: PRESTACION DE SERVICIOS
A37: Declaro voluntariamente y bajo la gravedad de juramento, que no soy responsable del impuesto del IVA. Declaro que mis ingresos mensuales provienen de la compensación por servicios personales y que para obtenerlos no he contratado ni vinculado dos (2) o más trabajadores asociados a la actividad. Lo anterior con el propósito de ser beneficiario en el cálculo de la retención en la fuente por concepto de honorarios, según lo dispuesto en el art 383 del estatuto tributario.
A44: FIRMA

Sheet Q

Sheet R
A1: =N!A1 -> Yumbo,15 Abril 2025 | E1: Cuenta de Cobro | G1: 23-977
A3: Yo | B3: Robert Andres Otero
A4: Con C.C | B4: 1118301529
A5: Manifiesto que: FUNDACION UNA MANO AMIGA A TIEMPO NIT: 901.369.891-9
A9: ME DEBE LA SUMA DE: | C9: 39300
A10: VALOR EN PESOS: | C10: {=UPPER([1]!NumLetra(C9,,"PESOS"))} -> TREINTA Y NUEVE MIL TRESCIENTOS PESOS
A11: POR CONCEPTO DE: | C11: PRESTACION DE SERVICIOS
A13: Declaro voluntariamente y bajo la gravedad de juramento, que no soy responsable del impuesto del IVA. Declaro que mis ingresos mensuales provienen de la compensación por servicios personales y que para obtenerlos no he contratado ni vinculado dos (2) o más trabajadores asociados a la actividad. Lo anterior con el propósito de ser beneficiario en el cálculo de la retención en la fuente por concepto de honorarios, según lo dispuesto en el art 383 del estatuto tributario.
A20: FIRMA

Sheet S
A1: S

Sheet T
A1: ='C'!A96 -> Yumbo,15 Abril 2025 | E1: Cuenta de Cobro | G1: 23-995
A3: Yo | B3: Tania Casallas
A4: Con C.C | B4: 1114838835
A5: Manifiesto que: FUNDACION UNA MANO AMIGA A TIEMPO NIT: 901.369.891-9
A9: ME DEBE LA SUMA DE: | C9: 352500
A10: VALOR EN PESOS: | C10: {=UPPER([1]!NumLetra(C9,,"PESOS"))} -> TRESCIENTOS CINCUENTA Y DOS MIL QUINIENTOS PESOS
A11: POR CONCEPTO DE: | C11: PRESTACION SERVICIOS
A13: Declaro voluntariamente y bajo la gravedad de juramento, que no soy responsable del impuesto del IVA. Declaro que mis ingresos mensuales provienen de la compensación por servicios personales y que para obtenerlos no he contratado ni vinculado dos (2) o más trabajadores asociados a la actividad. Lo anterior con el propósito de ser beneficiario en el cálculo de la retención en la fuente por concepto de honorarios, según lo dispuesto en el art 383 del estatuto tributario.
A20: FIRMA

Sheet U
A1: U

Sheet V

Sheet W

Sheet X

Sheet Y
A1: =A75 -> Yumbo,15 Abril 2025 | E1: Cuenta de Cobro | G1: 23-956
A3: Yo | B3: Yolanda Sanchez
A4: Con C.C | B4: 29940018
A5: Manifiesto que: FUNDACION UNA MANO AMIGA A TIEMPO NIT: 901.369.891-9
A9: ME DEBE LA SUMA DE: | C9: 344600
A10: VALOR EN PESOS: | C10: {=UPPER([1]!NumLetra(C9,,"PESOS"))} -> TRESCIENTOS CUARENTA Y CUATRO MIL SEISCIENTOS PESOS
A11: POR CONCEPTO DE: | C11: PRESTACION DE SERVICIOS
A13: Declaro voluntariamente y bajo la gravedad de juramento, que no soy responsable del impuesto del IVA. Declaro que mis ingresos mensuales provienen de la compensación por servicios personales y que para obtenerlos no he contratado ni vinculado dos (2) o más trabajadores asociados a la actividad. Lo anterior con el propósito de ser beneficiario en el cálculo de la retención en la fuente por concepto de honorarios, según lo dispuesto en el art 383 del estatuto tributario.
A21: FIRMA
A26: Yumbo, 15 febrero 2025 | E26: Cuenta de Cobro | G26: 23-986
A28: Yo | B28: Yuri Alexandra Anzola
A29: Con C.C | B29: 1118309124
A30: Manifiesto que: FUNDACION UNA MANO AMIGA A TIEMPO NIT: 901.369.891-9
A34: ME DEBE LA SUMA DE: | C34: 31000
A35: VALOR EN PESOS: | C35: {=UPPER([1]!NumLetra(C34,,"PESOS"))} -> TREINTA Y UN MIL PESOS
A36: POR CONCEPTO DE: | C36: PRESTACION DE SERVICIOS
A38: Declaro voluntariamente y bajo la gravedad de juramento, que no soy responsable del impuesto del IVA. Declaro que mis ingresos mensuales provienen de la compensación por servicios personales y que para obtenerlos no he contratado ni vinculado dos (2) o más trabajadores asociados a la actividad. Lo anterior con el propósito de ser beneficiario en el cálculo de la retención en la fuente por concepto de honorarios, según lo dispuesto en el art 383 del estatuto tributario.
A46: FIRMA
A50: =A75 -> Yumbo,15 Abril 2025 | E50: Cuenta de Cobro | G50: 23-985
A52: Yo | B52: ='[3]PLANILLA MATRIX'!$B$65 -> Loango Maria Yesenia
A53: Con C.C | B53: ='[3]PLANILLA MATRIX'!$A$65 -> 66932221
A54: Manifiesto que: FUNDACION UNA MANO AMIGA A TIEMPO NIT: 901.369.891-9
A58: ME DEBE LA SUMA DE: | C58: 305500
A59: VALOR EN PESOS: | C59: {=UPPER([1]!NumLetra(C58,,"PESOS"))} -> TRESCIENTOS CINCO MIL QUINIENTOS PESOS
A60: POR CONCEPTO DE: | C60: PRESTACION DE SERVICIOS
A62: Declaro voluntariamente y bajo la gravedad de juramento, que no soy responsable del impuesto del IVA. Declaro que mis ingresos mensuales provienen de la compensación por servicios personales y que para obtenerlos no he contratado ni vinculado dos (2) o más trabajadores asociados a la actividad. Lo anterior con el propósito de ser beneficiario en el cálculo de la retención en la fuente por concepto de honorarios, según lo dispuesto en el art 383 del estatuto tributario.
A70: FIRMA
A75: =A98 -> Yumbo,15 Abril 2025 | E75: Cuenta de Cobro | G75: 23-995
A77: Yo | B77: ='[10]PLANILLA MATRIX'!$B$92 -> Yamileth Miranda
A78: Con C.C | B78: ='[10]PLANILLA MATRIX'!$A$92 -> 314888255
A79: Manifiesto que: FUNDACION UNA MANO AMIGA A TIEMPO NIT: 901.369.891-9
A83: ME DEBE LA SUMA DE: | C83: 297000
A84: VALOR EN PESOS: | C84: {=UPPER([1]!NumLetra(C83,,"PESOS"))} -> DOSCIENTOS NOVENTA Y SIETE MIL PESOS
A85: POR CONCEPTO DE: | C85: PRESTACION SERVICIOS
A87: Declaro voluntariamente y bajo la gravedad de juramento, que no soy responsable del impuesto del IVA. Declaro que mis ingresos mensuales provienen de la compensación por servicios personales y que para obtenerlos no he contratado ni vinculado dos (2) o más trabajadores asociados a la actividad. Lo anterior con el propósito de ser beneficiario en el cálculo de la retención en la fuente por concepto de honorarios, según lo dispuesto en el art 383 del estatuto tributario.
A94: FIRMA
A98: =L!A50 -> Yumbo,15 Abril 2025 | E98: Cuenta de Cobro | G98: 23-995
A100: Yo | B100: Yepsy Sequera
A101: Con C.C | B101: 6663381
A102: Manifiesto que: FUNDACION UNA MANO AMIGA A TIEMPO NIT: 901.369.891-9
...

Sheet Z
A1: =A!A1 -> Yumbo,15 Abril 2025 | E1: Cuenta de Cobro | G1: 23-986
A3: Yo | B3: zharich nikol polanco garzón
A4: Con C.C | B4: 1193412592
A5: Manifiesto que: FUNDACION UNA MANO AMIGA A TIEMPO NIT: 901.369.891-9
A9: ME DEBE LA SUMA DE: | C9: 180000
A10: VALOR EN PESOS: | C10: {=UPPER([1]!NumLetra(C9,,"PESOS"))} -> CIENTO OCHENTA MIL PESOS
A11: POR CONCEPTO DE: | C11: PRESTACION DE SERVICIOS
A13: Declaro voluntariamente y bajo la gravedad de juramento, que no soy responsable del impuesto del IVA. Declaro que mis ingresos mensuales provienen de la compensación por servicios personales y que para obtenerlos no he contratado ni vinculado dos (2) o más trabajadores asociados a la actividad. Lo anterior con el propósito de ser beneficiario en el cálculo de la retención en la fuente por concepto de honorarios, según lo dispuesto en el art 383 del estatuto tributario.
A21: FIRMA
