Workbook

Sheet A
A1: 46160 | E1: Cuenta de Cobro | G1: 23-949
A3: Yo | B3: Anderson Posso
A4: Con C.C | B4: 1116373245
A5: Manifiesto que: FUNDACION UNA MANO AMIGA A TIEMPO NIT: 901.369.891-9
A9: ME DEBE LA SUMA DE: | C9: 80000
A10: VALOR EN PESOS: | C10: =ARRAY_CONSTRAIN(ARRAYFORMULA(UPPER([1]!NumLetra(C9,,"PESOS"))), 1, 1) -> #NAME?
A11: POR CONCEPTO DE: | C11: PRESTACION DE SERVICIOS
A13: Declaro voluntariamente y bajo la gravedad de juramento, que no soy responsable del impuesto del IVA. Declaro que mis ingresos mensuales provienen de la compensación por servicios personales y que para obtenerlos no he contratado ni vinculado dos (2) o más trabajadores asociados a la actividad. Lo anterior con el propósito de ser beneficiario en el cálculo de la retención en la fuente por concepto de honorarios, según lo dispuesto en el art 383 del estatuto tributario.
A21: FIRMA

Sheet C
A1: =A!A1 -> 46160 | E1: Cuenta de Cobro | G1: 23-949
A3: Yo | B3: Cristian Camilo Bedoya
A4: Con C.C | B4: 1042062690
A5: Manifiesto que: FUNDACION UNA MANO AMIGA A TIEMPO NIT: 901.369.891-9
A9: ME DEBE LA SUMA DE: | C9: 125700
A10: VALOR EN PESOS: | C10: =ARRAY_CONSTRAIN(ARRAYFORMULA(UPPER([1]!NumLetra(C9,,"PESOS"))), 1, 1) -> #NAME?
A11: POR CONCEPTO DE: | C11: PRESTACION DE SERVICIOS
A13: Declaro voluntariamente y bajo la gravedad de juramento, que no soy responsable del impuesto del IVA. Declaro que mis ingresos mensuales provienen de la compensación por servicios personales y que para obtenerlos no he contratado ni vinculado dos (2) o más trabajadores asociados a la actividad. Lo anterior con el propósito de ser beneficiario en el cálculo de la retención en la fuente por concepto de honorarios, según lo dispuesto en el art 383 del estatuto tributario.
A21: FIRMA
A24: =A1 -> 46160 | E24: Cuenta de Cobro | G24: 23-949
A26: Yo | B26: Camilo Lopéz
A27: Con C.C | B27: 1061694194
A28: Manifiesto que: FUNDACION UNA MANO AMIGA A TIEMPO NIT: 901.369.891-9
A32: ME DEBE LA SUMA DE: | C32: 210500
A33: VALOR EN PESOS: | C33: =ARRAY_CONSTRAIN(ARRAYFORMULA(UPPER([1]!NumLetra(C32,,"PESOS"))), 1, 1) -> #NAME?
A34: POR CONCEPTO DE: | C34: PRESTACION DE SERVICIOS
A36: Declaro voluntariamente y bajo la gravedad de juramento, que no soy responsable del impuesto del IVA. Declaro que mis ingresos mensuales provienen de la compensación por servicios personales y que para obtenerlos no he contratado ni vinculado dos (2) o más trabajadores asociados a la actividad. Lo anterior con el propósito de ser beneficiario en el cálculo de la retención en la fuente por concepto de honorarios, según lo dispuesto en el art 383 del estatuto tributario.
A44: FIRMA

Sheet J
A1: =A!A1 -> 46160 | E1: Cuenta de Cobro | G1: 23-949
A3: Yo | B3: Joeldrix Toro
A4: Con C.C | B4: 1116384064
A5: Manifiesto que: FUNDACION UNA MANO AMIGA A TIEMPO NIT: 901.369.891-9
A9: ME DEBE LA SUMA DE: | C9: 3800
A10: VALOR EN PESOS: | C10: =ARRAY_CONSTRAIN(ARRAYFORMULA(UPPER([1]!NumLetra(C9,,"PESOS"))), 1, 1) -> #NAME?
A11: POR CONCEPTO DE: | C11: PRESTACION DE SERVICIOS
A13: Declaro voluntariamente y bajo la gravedad de juramento, que no soy responsable del impuesto del IVA. Declaro que mis ingresos mensuales provienen de la compensación por servicios personales y que para obtenerlos no he contratado ni vinculado dos (2) o más trabajadores asociados a la actividad. Lo anterior con el propósito de ser beneficiario en el cálculo de la retención en la fuente por concepto de honorarios, según lo dispuesto en el art 383 del estatuto tributario.
A21: FIRMA
A24: =A1 -> 46160 | E24: Cuenta de Cobro | G24: 23-949
A26: Yo | B26: Joel Porras
A27: Con C.C | B27: 1116374701
A28: Manifiesto que: FUNDACION UNA MANO AMIGA A TIEMPO NIT: 901.369.891-9
A32: ME DEBE LA SUMA DE: | C32: 7620
A33: VALOR EN PESOS: | C33: SIETE MIL SEISCIENTOS VEINTE PESOS
A34: POR CONCEPTO DE: | C34: PRESTACION DE SERVICIOS
A36: Declaro voluntariamente y bajo la gravedad de juramento, que no soy responsable del impuesto del IVA. Declaro que mis ingresos mensuales provienen de la compensación por servicios personales y que para obtenerlos no he contratado ni vinculado dos (2) o más trabajadores asociados a la actividad. Lo anterior con el propósito de ser beneficiario en el cálculo de la retención en la fuente por concepto de honorarios, según lo dispuesto en el art 383 del estatuto tributario.
A44: FIRMA
A48: =A24 -> 46160 | E48: Cuenta de Cobro | G48: 23-949
A50: Yo | B50: Jhony Tobon
A51: Con C.C | B51: 1006536684
A52: Manifiesto que: FUNDACION UNA MANO AMIGA A TIEMPO NIT: 901.369.891-9
A56: ME DEBE LA SUMA DE: | C56: 40000
A57: VALOR EN PESOS: | C57: =ARRAY_CONSTRAIN(ARRAYFORMULA(UPPER([1]!NumLetra(C56,,"PESOS"))), 1, 1) -> #NAME?
A58: POR CONCEPTO DE: | C58: PRESTACION DE SERVICIOS
A60: Declaro voluntariamente y bajo la gravedad de juramento, que no soy responsable del impuesto del IVA. Declaro que mis ingresos mensuales provienen de la compensación por servicios personales y que para obtenerlos no he contratado ni vinculado dos (2) o más trabajadores asociados a la actividad. Lo anterior con el propósito de ser beneficiario en el cálculo de la retención en la fuente por concepto de honorarios, según lo dispuesto en el art 383 del estatuto tributario.
A68: FIRMA
A71: =A48 -> 46160 | E71: Cuenta de Cobro | G71: 23-949
A73: Yo | B73: Jhnoier de la Cruz
A74: Con C.C | B74: 1108252795
A75: Manifiesto que: FUNDACION UNA MANO AMIGA A TIEMPO NIT: 901.369.891-9
A79: ME DEBE LA SUMA DE: | C79: 363300
A80: VALOR EN PESOS: | C80: =ARRAY_CONSTRAIN(ARRAYFORMULA(UPPER([1]!NumLetra(C79,,"PESOS"))), 1, 1) -> #NAME?
A81: POR CONCEPTO DE: | C81: PRESTACION DE SERVICIOS
A83: Declaro voluntariamente y bajo la gravedad de juramento, que no soy responsable del impuesto del IVA. Declaro que mis ingresos mensuales provienen de la compensación por servicios personales y que para obtenerlos no he contratado ni vinculado dos (2) o más trabajadores asociados a la actividad. Lo anterior con el propósito de ser beneficiario en el cálculo de la retención en la fuente por concepto de honorarios, según lo dispuesto en el art 383 del estatuto tributario.
A91: FIRMA
A94: =A71 -> 46160 | E94: Cuenta de Cobro | G94: 23-949
A96: Yo | B96: Janeth Taborda
A97: Con C.C | B97: 1114727524
A98: Manifiesto que: FUNDACION UNA MANO AMIGA A TIEMPO NIT: 901.369.891-9
...

Sheet D
A1: =A!A1 -> 46160 | E1: Cuenta de Cobro | G1: 23-949
A3: Yo | B3: Diana Hungria
A4: Con C.C | B4: 31321813
A5: Manifiesto que: FUNDACION UNA MANO AMIGA A TIEMPO NIT: 901.369.891-9
A9: ME DEBE LA SUMA DE: | C9: 207600
A10: VALOR EN PESOS: | C10: =ARRAY_CONSTRAIN(ARRAYFORMULA(UPPER([1]!NumLetra(C9,,"PESOS"))), 1, 1) -> #NAME?
A11: POR CONCEPTO DE: | C11: PRESTACION DE SERVICIOS
A13: Declaro voluntariamente y bajo la gravedad de juramento, que no soy responsable del impuesto del IVA. Declaro que mis ingresos mensuales provienen de la compensación por servicios personales y que para obtenerlos no he contratado ni vinculado dos (2) o más trabajadores asociados a la actividad. Lo anterior con el propósito de ser beneficiario en el cálculo de la retención en la fuente por concepto de honorarios, según lo dispuesto en el art 383 del estatuto tributario.
A21: FIRMA

Sheet E
A1: =A!A1 -> 46160 | E1: Cuenta de Cobro | G1: 23-949
A3: Yo | B3: Edilvey Castillo
A4: Con C.C | B4: 1118287954
A5: Manifiesto que: FUNDACION UNA MANO AMIGA A TIEMPO NIT: 901.369.891-9
A9: ME DEBE LA SUMA DE: | C9: 151900
A10: VALOR EN PESOS: | C10: =ARRAY_CONSTRAIN(ARRAYFORMULA(UPPER([1]!NumLetra(C9,,"PESOS"))), 1, 1) -> #NAME?
A11: POR CONCEPTO DE: | C11: PRESTACION DE SERVICIOS
A13: Declaro voluntariamente y bajo la gravedad de juramento, que no soy responsable del impuesto del IVA. Declaro que mis ingresos mensuales provienen de la compensación por servicios personales y que para obtenerlos no he contratado ni vinculado dos (2) o más trabajadores asociados a la actividad. Lo anterior con el propósito de ser beneficiario en el cálculo de la retención en la fuente por concepto de honorarios, según lo dispuesto en el art 383 del estatuto tributario.
A21: FIRMA
A25: =A1 -> 46160 | E25: Cuenta de Cobro | G25: 23-949
A27: Yo | B27: Edward Martinez
A28: Con C.C | B28: 1109187236
A29: Manifiesto que: FUNDACION UNA MANO AMIGA A TIEMPO NIT: 901.369.891-9
A33: ME DEBE LA SUMA DE: | C33: 210500
A34: VALOR EN PESOS: | C34: =ARRAY_CONSTRAIN(ARRAYFORMULA(UPPER([1]!NumLetra(C33,,"PESOS"))), 1, 1) -> #NAME?
A35: POR CONCEPTO DE: | C35: PRESTACION DE SERVICIOS
A37: Declaro voluntariamente y bajo la gravedad de juramento, que no soy responsable del impuesto del IVA. Declaro que mis ingresos mensuales provienen de la compensación por servicios personales y que para obtenerlos no he contratado ni vinculado dos (2) o más trabajadores asociados a la actividad. Lo anterior con el propósito de ser beneficiario en el cálculo de la retención en la fuente por concepto de honorarios, según lo dispuesto en el art 383 del estatuto tributario.
A45: FIRMA

Sheet F
A1: =A!A1 -> 46160 | E1: Cuenta de Cobro | G1: 23-949
A3: Yo | B3: Frank Robert Vergara
A4: Con C.C | B4: 16462862
A5: Manifiesto que: FUNDACION UNA MANO AMIGA A TIEMPO NIT: 901.369.891-9
A9: ME DEBE LA SUMA DE: | C9: 125700
A10: VALOR EN PESOS: | C10: =ARRAY_CONSTRAIN(ARRAYFORMULA(UPPER([1]!NumLetra(C9,,"PESOS"))), 1, 1) -> #NAME?
A11: POR CONCEPTO DE: | C11: PRESTACION DE SERVICIOS
A13: Declaro voluntariamente y bajo la gravedad de juramento, que no soy responsable del impuesto del IVA. Declaro que mis ingresos mensuales provienen de la compensación por servicios personales y que para obtenerlos no he contratado ni vinculado dos (2) o más trabajadores asociados a la actividad. Lo anterior con el propósito de ser beneficiario en el cálculo de la retención en la fuente por concepto de honorarios, según lo dispuesto en el art 383 del estatuto tributario.
A21: FIRMA
A24: =A!A1 -> 46160 | E24: Cuenta de Cobro | G24: 23-949
A26: Yo | B26: Franklin Rivera
A27: Con C.C | B27: 1012342318
A28: Manifiesto que: FUNDACION UNA MANO AMIGA A TIEMPO NIT: 901.369.891-9
A32: ME DEBE LA SUMA DE: | C32: 125700
A33: VALOR EN PESOS: | C33: =ARRAY_CONSTRAIN(ARRAYFORMULA(UPPER([1]!NumLetra(C32,,"PESOS"))), 1, 1) -> #NAME?
A34: POR CONCEPTO DE: | C34: PRESTACION DE SERVICIOS
A36: Declaro voluntariamente y bajo la gravedad de juramento, que no soy responsable del impuesto del IVA. Declaro que mis ingresos mensuales provienen de la compensación por servicios personales y que para obtenerlos no he contratado ni vinculado dos (2) o más trabajadores asociados a la actividad. Lo anterior con el propósito de ser beneficiario en el cálculo de la retención en la fuente por concepto de honorarios, según lo dispuesto en el art 383 del estatuto tributario.
A44: FIRMA

Sheet G
A1: =A!A1 -> 46160 | E1: Cuenta de Cobro | G1: 23-949
A3: Yo | B3: Gabriel Guerrrero
A4: Con C.C | B4: 1109920831
A5: Manifiesto que: FUNDACION UNA MANO AMIGA A TIEMPO NIT: 901.369.891-9
A9: ME DEBE LA SUMA DE: | C9: 126300
A10: VALOR EN PESOS: | C10: CIENTO VEINTE MIL TRESCIENTOS PESOS
A11: POR CONCEPTO DE: | C11: PRESTACION DE SERVICIOS
A13: Declaro voluntariamente y bajo la gravedad de juramento, que no soy responsable del impuesto del IVA. Declaro que mis ingresos mensuales provienen de la compensación por servicios personales y que para obtenerlos no he contratado ni vinculado dos (2) o más trabajadores asociados a la actividad. Lo anterior con el propósito de ser beneficiario en el cálculo de la retención en la fuente por concepto de honorarios, según lo dispuesto en el art 383 del estatuto tributario.
A21: FIRMA

Sheet H
A1: =A!A1 -> 46160 | E1: Cuenta de Cobro | G1: 23-949
A3: Yo | B3: Heber Cardenas
A4: Con C.C | B4: 1006536580
A5: Manifiesto que: FUNDACION UNA MANO AMIGA A TIEMPO NIT: 901.369.891-9
A9: ME DEBE LA SUMA DE: | C9: 106300
A10: VALOR EN PESOS: | C10: CIENTO SIES MIL TRESCIENTOS PESOS
A11: POR CONCEPTO DE: | C11: PRESTACION DE SERVICIOS
A13: Declaro voluntariamente y bajo la gravedad de juramento, que no soy responsable del impuesto del IVA. Declaro que mis ingresos mensuales provienen de la compensación por servicios personales y que para obtenerlos no he contratado ni vinculado dos (2) o más trabajadores asociados a la actividad. Lo anterior con el propósito de ser beneficiario en el cálculo de la retención en la fuente por concepto de honorarios, según lo dispuesto en el art 383 del estatuto tributario.
A21: FIRMA
A25: =A1 -> 46160 | E25: Cuenta de Cobro | G25: 23-949
A27: Yo | B27: Herney Zuñiga
A28: Con C.C | B28: 1116373114
A29: Manifiesto que: FUNDACION UNA MANO AMIGA A TIEMPO NIT: 901.369.891-9
A33: ME DEBE LA SUMA DE: | C33: 126300
A34: VALOR EN PESOS: | C34: CIENTO VEINTI SEIS MIL TRESCIENTOS
A35: POR CONCEPTO DE: | C35: PRESTACION DE SERVICIOS
A37: Declaro voluntariamente y bajo la gravedad de juramento, que no soy responsable del impuesto del IVA. Declaro que mis ingresos mensuales provienen de la compensación por servicios personales y que para obtenerlos no he contratado ni vinculado dos (2) o más trabajadores asociados a la actividad. Lo anterior con el propósito de ser beneficiario en el cálculo de la retención en la fuente por concepto de honorarios, según lo dispuesto en el art 383 del estatuto tributario.
A45: FIRMA

Sheet K
A1: =A!A1 -> 46160 | E1: Cuenta de Cobro | G1: 23-949
A3: Yo | B3: Kensy Franco
A4: Con C.C | B4: 1052730520
A5: Manifiesto que: FUNDACION UNA MANO AMIGA A TIEMPO NIT: 901.369.891-9
A9: ME DEBE LA SUMA DE: | C9: 126300
A10: VALOR EN PESOS: | C10: CIENTO VEINTISEIS MIL TRESCIENTOS PESOS
A11: POR CONCEPTO DE: | C11: PRESTACION DE SERVICIOS
A13: Declaro voluntariamente y bajo la gravedad de juramento, que no soy responsable del impuesto del IVA. Declaro que mis ingresos mensuales provienen de la compensación por servicios personales y que para obtenerlos no he contratado ni vinculado dos (2) o más trabajadores asociados a la actividad. Lo anterior con el propósito de ser beneficiario en el cálculo de la retención en la fuente por concepto de honorarios, según lo dispuesto en el art 383 del estatuto tributario.
A21: FIRMA
A24: =A1 -> 46160 | E24: Cuenta de Cobro | G24: 23-949
A26: Yo | B26: Karol Valero
A27: Con C.C | B27: 1006171949
A28: Manifiesto que: FUNDACION UNA MANO AMIGA A TIEMPO NIT: 901.369.891-9
A32: ME DEBE LA SUMA DE: | C32: 207600
A33: VALOR EN PESOS: | C33: =ARRAY_CONSTRAIN(ARRAYFORMULA(UPPER([1]!NumLetra(C32,,"PESOS"))), 1, 1) -> #NAME?
A34: POR CONCEPTO DE: | C34: PRESTACION DE SERVICIOS
A36: Declaro voluntariamente y bajo la gravedad de juramento, que no soy responsable del impuesto del IVA. Declaro que mis ingresos mensuales provienen de la compensación por servicios personales y que para obtenerlos no he contratado ni vinculado dos (2) o más trabajadores asociados a la actividad. Lo anterior con el propósito de ser beneficiario en el cálculo de la retención en la fuente por concepto de honorarios, según lo dispuesto en el art 383 del estatuto tributario.
A44: FIRMA
A47: =A24 -> 46160 | E47: Cuenta de Cobro | G47: 23-949
A49: Yo | B49: Karen Gonzales
A50: Con C.C | B50: 1061705829
A51: Manifiesto que: FUNDACION UNA MANO AMIGA A TIEMPO NIT: 901.369.891-9
A55: ME DEBE LA SUMA DE: | C55: 259500
A56: VALOR EN PESOS: | C56: =ARRAY_CONSTRAIN(ARRAYFORMULA(UPPER([1]!NumLetra(C55,,"PESOS"))), 1, 1) -> #NAME?
A57: POR CONCEPTO DE: | C57: PRESTACION DE SERVICIOS
A59: Declaro voluntariamente y bajo la gravedad de juramento, que no soy responsable del impuesto del IVA. Declaro que mis ingresos mensuales provienen de la compensación por servicios personales y que para obtenerlos no he contratado ni vinculado dos (2) o más trabajadores asociados a la actividad. Lo anterior con el propósito de ser beneficiario en el cálculo de la retención en la fuente por concepto de honorarios, según lo dispuesto en el art 383 del estatuto tributario.
A67: FIRMA
A70: =A47 -> 46160 | E70: Cuenta de Cobro | G70: 23-949
A72: Yo | B72: Karen Galvis
A73: Con C.C | B73: 1118306268
A74: Manifiesto que: FUNDACION UNA MANO AMIGA A TIEMPO NIT: 901.369.891-9
A78: ME DEBE LA SUMA DE: | C78: 126300
A79: VALOR EN PESOS: | C79: CIENTO VEINTI SEIS MIL TRESCIENTOS PESOS
A80: POR CONCEPTO DE: | C80: PRESTACION DE SERVICIOS
A82: Declaro voluntariamente y bajo la gravedad de juramento, que no soy responsable del impuesto del IVA. Declaro que mis ingresos mensuales provienen de la compensación por servicios personales y que para obtenerlos no he contratado ni vinculado dos (2) o más trabajadores asociados a la actividad. Lo anterior con el propósito de ser beneficiario en el cálculo de la retención en la fuente por concepto de honorarios, según lo dispuesto en el art 383 del estatuto tributario.
A90: FIRMA
A93: =A70 -> 46160 | E93: Cuenta de Cobro | G93: 23-949
A95: Yo | B95: Kevin Galvis
A96: Con C.C | B96: 1118301640
A97: Manifiesto que: FUNDACION UNA MANO AMIGA A TIEMPO NIT: 901.369.891-9
...

Sheet L
A1: =A!A1 -> 46160 | E1: Cuenta de Cobro | G1: 23-949
A3: Yo | B3: Leider Tintinago
A4: Con C.C | B4: 1058786606
A5: Manifiesto que: FUNDACION UNA MANO AMIGA A TIEMPO NIT: 901.369.891-9
A9: ME DEBE LA SUMA DE: | C9: 335200
A10: VALOR EN PESOS: | C10: =ARRAY_CONSTRAIN(ARRAYFORMULA(UPPER([1]!NumLetra(C9,,"PESOS"))), 1, 1) -> #NAME?
A11: POR CONCEPTO DE: | C11: PRESTACION DE SERVICIOS
A13: Declaro voluntariamente y bajo la gravedad de juramento, que no soy responsable del impuesto del IVA. Declaro que mis ingresos mensuales provienen de la compensación por servicios personales y que para obtenerlos no he contratado ni vinculado dos (2) o más trabajadores asociados a la actividad. Lo anterior con el propósito de ser beneficiario en el cálculo de la retención en la fuente por concepto de honorarios, según lo dispuesto en el art 383 del estatuto tributario.
A21: FIRMA
A25: =A1 -> 46160 | E25: Cuenta de Cobro | G25: 23-949
A27: Yo | B27: Lina Gutierrez
A28: Con C.C | B28: 1118304245
A29: Manifiesto que: FUNDACION UNA MANO AMIGA A TIEMPO NIT: 901.369.891-9
A33: ME DEBE LA SUMA DE: | C33: 12700
A34: VALOR EN PESOS: | C34: DOCE MIL SETECIENTOS PESOS
A35: POR CONCEPTO DE: | C35: PRESTACION DE SERVICIOS
A37: Declaro voluntariamente y bajo la gravedad de juramento, que no soy responsable del impuesto del IVA. Declaro que mis ingresos mensuales provienen de la compensación por servicios personales y que para obtenerlos no he contratado ni vinculado dos (2) o más trabajadores asociados a la actividad. Lo anterior con el propósito de ser beneficiario en el cálculo de la retención en la fuente por concepto de honorarios, según lo dispuesto en el art 383 del estatuto tributario.
A45: FIRMA
A48: =A25 -> 46160 | E48: Cuenta de Cobro | G48: 23-949
A50: Yo | B50: Lucero Reina
A51: Con C.C | B51: 1193475621
A52: Manifiesto que: FUNDACION UNA MANO AMIGA A TIEMPO NIT: 901.369.891-9
A56: ME DEBE LA SUMA DE: | C56: 224500
A57: VALOR EN PESOS: | C57: =ARRAY_CONSTRAIN(ARRAYFORMULA(UPPER([1]!NumLetra(C56,,"PESOS"))), 1, 1) -> #NAME?
A58: POR CONCEPTO DE: | C58: PRESTACION DE SERVICIOS
A60: Declaro voluntariamente y bajo la gravedad de juramento, que no soy responsable del impuesto del IVA. Declaro que mis ingresos mensuales provienen de la compensación por servicios personales y que para obtenerlos no he contratado ni vinculado dos (2) o más trabajadores asociados a la actividad. Lo anterior con el propósito de ser beneficiario en el cálculo de la retención en la fuente por concepto de honorarios, según lo dispuesto en el art 383 del estatuto tributario.
A68: FIRMA
A72: =A48 -> 46160 | E72: Cuenta de Cobro | G72: 23-949
A74: Yo | B74: Laura Ordoñez
A75: Con C.C | B75: 1090274163
A76: Manifiesto que: FUNDACION UNA MANO AMIGA A TIEMPO NIT: 901.369.891-9
A80: ME DEBE LA SUMA DE: | C80: 12700
A81: VALOR EN PESOS: | C81: DOCE MIL SETECIENTOS PESOS
A82: POR CONCEPTO DE: | C82: PRESTACION DE SERVICIOS
A84: Declaro voluntariamente y bajo la gravedad de juramento, que no soy responsable del impuesto del IVA. Declaro que mis ingresos mensuales provienen de la compensación por servicios personales y que para obtenerlos no he contratado ni vinculado dos (2) o más trabajadores asociados a la actividad. Lo anterior con el propósito de ser beneficiario en el cálculo de la retención en la fuente por concepto de honorarios, según lo dispuesto en el art 383 del estatuto tributario.
A92: FIRMA
A95: =A72 -> 46160 | E95: Cuenta de Cobro | G95: 23-949
A97: Yo | B97: Liseth Ibarguen
A98: Con C.C | B98: 1006536547
A99: Manifiesto que: FUNDACION UNA MANO AMIGA A TIEMPO NIT: 901.369.891-9
...

Sheet M
A1: =A!A1 -> 46160 | E1: Cuenta de Cobro | G1: 23-949
A3: Yo | B3: Michael Paz
A4: Con C.C | B4: 1116372497
A5: Manifiesto que: FUNDACION UNA MANO AMIGA A TIEMPO NIT: 901.369.891-9
A9: ME DEBE LA SUMA DE: | C9: 123800
A10: VALOR EN PESOS: | C10: =ARRAY_CONSTRAIN(ARRAYFORMULA(UPPER([1]!NumLetra(C9,,"PESOS"))), 1, 1) -> #NAME?
A11: POR CONCEPTO DE: | C11: PRESTACION DE SERVICIOS
A13: Declaro voluntariamente y bajo la gravedad de juramento, que no soy responsable del impuesto del IVA. Declaro que mis ingresos mensuales provienen de la compensación por servicios personales y que para obtenerlos no he contratado ni vinculado dos (2) o más trabajadores asociados a la actividad. Lo anterior con el propósito de ser beneficiario en el cálculo de la retención en la fuente por concepto de honorarios, según lo dispuesto en el art 383 del estatuto tributario.
A21: FIRMA
A24: =A1 -> 46160 | E24: Cuenta de Cobro | G24: 23-949
A26: Yo | B26: Michael David Montoya
A27: Con C.C | B27: 1109114434
A28: Manifiesto que: FUNDACION UNA MANO AMIGA A TIEMPO NIT: 901.369.891-9
A32: ME DEBE LA SUMA DE: | C32: 7600
A33: VALOR EN PESOS: | C33: =ARRAY_CONSTRAIN(ARRAYFORMULA(UPPER([1]!NumLetra(C32,,"PESOS"))), 1, 1) -> #NAME?
A34: POR CONCEPTO DE: | C34: PRESTACION DE SERVICIOS
A36: Declaro voluntariamente y bajo la gravedad de juramento, que no soy responsable del impuesto del IVA. Declaro que mis ingresos mensuales provienen de la compensación por servicios personales y que para obtenerlos no he contratado ni vinculado dos (2) o más trabajadores asociados a la actividad. Lo anterior con el propósito de ser beneficiario en el cálculo de la retención en la fuente por concepto de honorarios, según lo dispuesto en el art 383 del estatuto tributario.
A44: FIRMA
A47: =A24 -> 46160 | E47: Cuenta de Cobro | G47: 23-949
A49: Yo | B49: Monica Lopez
A50: Con C.C | B50: 1118289393
A51: Manifiesto que: FUNDACION UNA MANO AMIGA A TIEMPO NIT: 901.369.891-9
A55: ME DEBE LA SUMA DE: | C55: 126300
A56: VALOR EN PESOS: | C56: CIENTO VEINTISEIS MIL TRESCIENTOS PESOS
A57: POR CONCEPTO DE: | C57: PRESTACION DE SERVICIOS
A59: Declaro voluntariamente y bajo la gravedad de juramento, que no soy responsable del impuesto del IVA. Declaro que mis ingresos mensuales provienen de la compensación por servicios personales y que para obtenerlos no he contratado ni vinculado dos (2) o más trabajadores asociados a la actividad. Lo anterior con el propósito de ser beneficiario en el cálculo de la retención en la fuente por concepto de honorarios, según lo dispuesto en el art 383 del estatuto tributario.
A67: FIRMA
A70: =A47 -> 46160 | E70: Cuenta de Cobro | G70: 23-949
A72: Yo | B72: Maryuri Copete
A73: Con C.C | B73: 35820110
A74: Manifiesto que: FUNDACION UNA MANO AMIGA A TIEMPO NIT: 901.369.891-9
A78: ME DEBE LA SUMA DE: | C78: 207600
A79: VALOR EN PESOS: | C79: =ARRAY_CONSTRAIN(ARRAYFORMULA(UPPER([1]!NumLetra(C78,,"PESOS"))), 1, 1) -> #NAME?
A80: POR CONCEPTO DE: | C80: PRESTACION DE SERVICIOS
A82: Declaro voluntariamente y bajo la gravedad de juramento, que no soy responsable del impuesto del IVA. Declaro que mis ingresos mensuales provienen de la compensación por servicios personales y que para obtenerlos no he contratado ni vinculado dos (2) o más trabajadores asociados a la actividad. Lo anterior con el propósito de ser beneficiario en el cálculo de la retención en la fuente por concepto de honorarios, según lo dispuesto en el art 383 del estatuto tributario.
A90: FIRMA
A94: =A70 -> 46160 | E94: Cuenta de Cobro | G94: 23-949
A96: Yo | B96: Mabel Obando
A97: Con C.C | B97: 1116373058
A98: Manifiesto que: FUNDACION UNA MANO AMIGA A TIEMPO NIT: 901.369.891-9
...

Sheet R
A1: =A!A1 -> 46160 | E1: Cuenta de Cobro | G1: 23-949
A3: Yo | B3: Rodrigo Porras
A4: Con C.C | B4: 1118296803
A5: Manifiesto que: FUNDACION UNA MANO AMIGA A TIEMPO NIT: 901.369.891-9
A9: ME DEBE LA SUMA DE: | C9: 207600
A10: VALOR EN PESOS: | C10: =ARRAY_CONSTRAIN(ARRAYFORMULA(UPPER([1]!NumLetra(C9,,"PESOS"))), 1, 1) -> #NAME?
A11: POR CONCEPTO DE: | C11: PRESTACION DE SERVICIOS
A13: Declaro voluntariamente y bajo la gravedad de juramento, que no soy responsable del impuesto del IVA. Declaro que mis ingresos mensuales provienen de la compensación por servicios personales y que para obtenerlos no he contratado ni vinculado dos (2) o más trabajadores asociados a la actividad. Lo anterior con el propósito de ser beneficiario en el cálculo de la retención en la fuente por concepto de honorarios, según lo dispuesto en el art 383 del estatuto tributario.
A21: FIRMA

Sheet S
A1: =A!A1 -> 46160 | E1: Cuenta de Cobro | G1: 23-949
A3: Yo | B3: Edward Steven Martinez
A4: Con C.C | B4: 1109187236
A5: Manifiesto que: FUNDACION UNA MANO AMIGA A TIEMPO NIT: 901.369.891-9
A9: ME DEBE LA SUMA DE: | C9: 42100
A10: VALOR EN PESOS: | C10: CUARENTA Y DOS MIL CIEN PESOS
A11: POR CONCEPTO DE: | C11: PRESTACION DE SERVICIOS
A13: Declaro voluntariamente y bajo la gravedad de juramento, que no soy responsable del impuesto del IVA. Declaro que mis ingresos mensuales provienen de la compensación por servicios personales y que para obtenerlos no he contratado ni vinculado dos (2) o más trabajadores asociados a la actividad. Lo anterior con el propósito de ser beneficiario en el cálculo de la retención en la fuente por concepto de honorarios, según lo dispuesto en el art 383 del estatuto tributario.
A21: FIRMA
A25: =A!A1 -> 46160 | E25: Cuenta de Cobro | G25: 23-949
A27: Yo | B27: Sarah Vasquez
A28: Con C.C | B28: 1116374153
A29: Manifiesto que: FUNDACION UNA MANO AMIGA A TIEMPO NIT: 901.369.891-9
A33: ME DEBE LA SUMA DE: | C33: 21975
A34: VALOR EN PESOS: | C34: VEINTI UN MIL NOVECIENTOS SETENTA Y CINCO PESOS
A35: POR CONCEPTO DE: | C35: PRESTACION DE SERVICIOS
A37: Declaro voluntariamente y bajo la gravedad de juramento, que no soy responsable del impuesto del IVA. Declaro que mis ingresos mensuales provienen de la compensación por servicios personales y que para obtenerlos no he contratado ni vinculado dos (2) o más trabajadores asociados a la actividad. Lo anterior con el propósito de ser beneficiario en el cálculo de la retención en la fuente por concepto de honorarios, según lo dispuesto en el art 383 del estatuto tributario.
A45: FIRMA
A50: =A!A1 -> 46160 | E50: Cuenta de Cobro
A52: Yo | B52: SARAI REYES
A53: Con C.C | B53: 1114624383
A54: Manifiesto que: FUNDACION UNA MANO AMIGA A TIEMPO NIT: 901.369.891-9
A58: ME DEBE LA SUMA DE: | C58: 12700
A59: VALOR EN PESOS: | C59: DOCE MIL SETECIENTOS PESOS
A60: POR CONCEPTO DE: | C60: PRESTACION DE SERVICIOS
A62: Declaro voluntariamente y bajo la gravedad de juramento, que no soy responsable del impuesto del IVA. Declaro que mis ingresos mensuales provienen de la compensación por servicios personales y que para obtenerlos no he contratado ni vinculado dos (2) o más trabajadores asociados a la actividad. Lo anterior con el propósito de ser beneficiario en el cálculo de la retención en la fuente por concepto de honorarios, según lo dispuesto en el art 383 del estatuto tributario.
A70: FIRMA

Sheet N
A1: =A!A1 -> 46160 | E1: Cuenta de Cobro | G1: 23-949
A3: Yo | B3: Nicolle Martinez
A4: Con C.C | B4: 1116372289
A5: Manifiesto que: FUNDACION UNA MANO AMIGA A TIEMPO NIT: 901.369.891-9
A9: ME DEBE LA SUMA DE: | C9: 126300
A10: VALOR EN PESOS: | C10: CIENTO VEINTI SEIS MIL TRESCIENTOS PESOS
A11: POR CONCEPTO DE: | C11: PRESTACION DE SERVICIOS
A13: Declaro voluntariamente y bajo la gravedad de juramento, que no soy responsable del impuesto del IVA. Declaro que mis ingresos mensuales provienen de la compensación por servicios personales y que para obtenerlos no he contratado ni vinculado dos (2) o más trabajadores asociados a la actividad. Lo anterior con el propósito de ser beneficiario en el cálculo de la retención en la fuente por concepto de honorarios, según lo dispuesto en el art 383 del estatuto tributario.
A21: FIRMA
A25: =A!A1 -> 46160 | E25: Cuenta de Cobro | G25: 23-949
A27: Yo | B27: Nathaly Bolaños
A28: Con C.C | B28: 1116373199
A29: Manifiesto que: FUNDACION UNA MANO AMIGA A TIEMPO NIT: 901.369.891-9
A33: ME DEBE LA SUMA DE: | C33: 420320
A34: VALOR EN PESOS: | C34: CUATROSCIENTOS VEINTE MIL TRESCIENTOS VEINTE PESOS
A35: POR CONCEPTO DE: | C35: PRESTACION DE SERVICIOS
A37: Declaro voluntariamente y bajo la gravedad de juramento, que no soy responsable del impuesto del IVA. Declaro que mis ingresos mensuales provienen de la compensación por servicios personales y que para obtenerlos no he contratado ni vinculado dos (2) o más trabajadores asociados a la actividad. Lo anterior con el propósito de ser beneficiario en el cálculo de la retención en la fuente por concepto de honorarios, según lo dispuesto en el art 383 del estatuto tributario.
A45: FIRMA

Sheet V
A1: =A!A1 -> 46160 | E1: Cuenta de Cobro | G1: 23-949
A3: Yo | B3: Valeri Chocue
A4: Con C.C | B4: 1005833509
A5: Manifiesto que: FUNDACION UNA MANO AMIGA A TIEMPO NIT: 901.369.891-9
A9: ME DEBE LA SUMA DE: | C9: 140700
A10: VALOR EN PESOS: | C10: =ARRAY_CONSTRAIN(ARRAYFORMULA(UPPER([1]!NumLetra(C9,,"PESOS"))), 1, 1) -> #NAME?
A11: POR CONCEPTO DE: | C11: PRESTACION DE SERVICIOS
A13: Declaro voluntariamente y bajo la gravedad de juramento, que no soy responsable del impuesto del IVA. Declaro que mis ingresos mensuales provienen de la compensación por servicios personales y que para obtenerlos no he contratado ni vinculado dos (2) o más trabajadores asociados a la actividad. Lo anterior con el propósito de ser beneficiario en el cálculo de la retención en la fuente por concepto de honorarios, según lo dispuesto en el art 383 del estatuto tributario.
A21: FIRMA

Sheet Y
A1: =A!A1 -> 46160 | E1: Cuenta de Cobro | G1: 23-949
A3: Yo | B3: Yordan Lita
A4: Con C.C | B4: 1192761495
A5: Manifiesto que: FUNDACION UNA MANO AMIGA A TIEMPO NIT: 901.369.891-9
A9: ME DEBE LA SUMA DE: | C9: 55000
A10: VALOR EN PESOS: | C10: =ARRAY_CONSTRAIN(ARRAYFORMULA(UPPER([1]!NumLetra(C9,,"PESOS"))), 1, 1) -> #NAME?
A11: POR CONCEPTO DE: | C11: PRESTACION DE SERVICIOS
A13: Declaro voluntariamente y bajo la gravedad de juramento, que no soy responsable del impuesto del IVA. Declaro que mis ingresos mensuales provienen de la compensación por servicios personales y que para obtenerlos no he contratado ni vinculado dos (2) o más trabajadores asociados a la actividad. Lo anterior con el propósito de ser beneficiario en el cálculo de la retención en la fuente por concepto de honorarios, según lo dispuesto en el art 383 del estatuto tributario.
A21: FIRMA

Sheet W
A1: =A!A1 -> 46160 | E1: Cuenta de Cobro | G1: 23-949
A3: Yo | B3: Winston Alvares
A4: Con C.C | B4: 1091273757
A5: Manifiesto que: FUNDACION UNA MANO AMIGA A TIEMPO NIT: 901.369.891-9
A9: ME DEBE LA SUMA DE: | C9: 100000
A10: VALOR EN PESOS: | C10: Cien mil pesos.
A11: POR CONCEPTO DE: | C11: PRESTACION DE SERVICIOS
A13: Declaro voluntariamente y bajo la gravedad de juramento, que no soy responsable del impuesto del IVA. Declaro que mis ingresos mensuales provienen de la compensación por servicios personales y que para obtenerlos no he contratado ni vinculado dos (2) o más trabajadores asociados a la actividad. Lo anterior con el propósito de ser beneficiario en el cálculo de la retención en la fuente por concepto de honorarios, según lo dispuesto en el art 383 del estatuto tributario.
A21: FIRMA
